2020-05-05 18:45:34,191 - e:/桌面/,/work_project/Car_Engine/code/CarEngine/codeV3/mid_kafka_operate.py[line:60] - ERROR: kafka consumer error 
2020-05-05 18:47:03,188 - e:/桌面/,/work_project/Car_Engine/code/CarEngine/codeV3/mid_kafka_operate.py[line:60] - ERROR: kafka consumer error 
2020-05-05 18:53:01,298 - e:/桌面/,/work_project/Car_Engine/code/CarEngine/codeV3/mid_kafka_operate.py[line:60] - ERROR: kafka consumer error 
2020-05-05 18:54:18,029 - e:/桌面/,/work_project/Car_Engine/code/CarEngine/codeV3/mid_kafka_operate.py[line:60] - ERROR: kafka consumer error 
2020-05-05 18:56:02,684 - e:/桌面/,/work_project/Car_Engine/code/CarEngine/codeV3/mid_kafka_operate.py[line:60] - ERROR: kafka consumer error 
2020-05-05 18:59:42,114 - .\mid_kafka_operate.py[line:60] - ERROR: kafka consumer error 
2020-05-05 19:01:15,735 - e:/桌面/,/work_project/Car_Engine/code/CarEngine/codeV3/mid_kafka_operate.py[line:60] - ERROR: kafka consumer error 
2020-05-05 21:43:10,734 - e:/桌面/,/work_project/Car_Engine/code/CarEngine/codeV3/mid_dir_operator.py[line:71] - ERROR: unzip faile [WinError 3] The system cannot find the path specified: 'e:\\桌面\\,\\work_project\\Car_Engine\\code\\CarEngine\\codeV3\\datasetfiles\\王亚林50\\gangbi3zhongdu'
2020-05-06 09:07:04,050 - e:/桌面/,/work_project/Car_Engine/code/CarEngine/codeV3/mid_dir_operator.py[line:77] - ERROR: unzip faile File is not a zip file
2020-05-06 09:08:21,880 - e:/桌面/,/work_project/Car_Engine/code/CarEngine/codeV3/mid_dir_operator.py[line:75] - ERROR: unzip faile [WinError 183] Cannot create a file when that file already exists: '王亚林50'
2020-05-06 09:08:47,925 - e:/桌面/,/work_project/Car_Engine/code/CarEngine/codeV3/mid_dir_operator.py[line:75] - ERROR: unzip faile File is not a zip file
2020-05-06 10:31:19,074 - e:/桌面/app/work_project/Car_Engine/code/CarEngine/codeV3/mid_dir_operator.py[line:79] - ERROR: not file [Errno 13] Permission denied: 'e:/桌面/app/work_project/Car_Engine/code/CarEngine/codeV3/datasetfiles/王亚林50'
2020-05-06 10:31:19,086 - e:/桌面/app/work_project/Car_Engine/code/CarEngine/codeV3/mid_dir_operator.py[line:79] - ERROR: not file [Errno 13] Permission denied: 'e:/桌面/app/work_project/Car_Engine/code/CarEngine/codeV3/datasetfiles/王亚林50/gangbi3zhongdu/'
2020-05-06 10:31:19,088 - e:/桌面/app/work_project/Car_Engine/code/CarEngine/codeV3/mid_dir_operator.py[line:79] - ERROR: not file [Errno 13] Permission denied: 'e:/桌面/app/work_project/Car_Engine/code/CarEngine/codeV3/datasetfiles/王亚林50/gangbi3zhongdu/nEO_IMG_IV000261.JPG'
2020-05-06 10:31:19,089 - e:/桌面/app/work_project/Car_Engine/code/CarEngine/codeV3/mid_dir_operator.py[line:79] - ERROR: not file [Errno 13] Permission denied: 'e:/桌面/app/work_project/Car_Engine/code/CarEngine/codeV3/datasetfiles/王亚林50/gangbi3zhongdu/IV002120.JPG'
2020-05-06 10:31:19,090 - e:/桌面/app/work_project/Car_Engine/code/CarEngine/codeV3/mid_dir_operator.py[line:79] - ERROR: not file [Errno 13] Permission denied: 'e:/桌面/app/work_project/Car_Engine/code/CarEngine/codeV3/datasetfiles/王亚林50/gangbi3zhongdu/IV002180.JPG'
2020-05-06 10:31:19,091 - e:/桌面/app/work_project/Car_Engine/code/CarEngine/codeV3/mid_dir_operator.py[line:79] - ERROR: not file [Errno 13] Permission denied: 'e:/桌面/app/work_project/Car_Engine/code/CarEngine/codeV3/datasetfiles/王亚林50/gangbi3zhongdu/nEO_IMG_IV000322 (2).JPG'
2020-05-06 10:31:19,093 - e:/桌面/app/work_project/Car_Engine/code/CarEngine/codeV3/mid_dir_operator.py[line:79] - ERROR: not file [Errno 13] Permission denied: 'e:/桌面/app/work_project/Car_Engine/code/CarEngine/codeV3/datasetfiles/王亚林50/gangbi3zhongdu/IV002100.JPG'
2020-05-06 10:31:19,094 - e:/桌面/app/work_project/Car_Engine/code/CarEngine/codeV3/mid_dir_operator.py[line:79] - ERROR: not file [Errno 13] Permission denied: 'e:/桌面/app/work_project/Car_Engine/code/CarEngine/codeV3/datasetfiles/王亚林50/gangbi2qingdu/'
2020-05-06 10:31:19,095 - e:/桌面/app/work_project/Car_Engine/code/CarEngine/codeV3/mid_dir_operator.py[line:79] - ERROR: not file [Errno 13] Permission denied: 'e:/桌面/app/work_project/Car_Engine/code/CarEngine/codeV3/datasetfiles/王亚林50/gangbi2qingdu/IV7L0121 (3).JPG'
2020-05-06 10:31:19,096 - e:/桌面/app/work_project/Car_Engine/code/CarEngine/codeV3/mid_dir_operator.py[line:79] - ERROR: not file [Errno 13] Permission denied: 'e:/桌面/app/work_project/Car_Engine/code/CarEngine/codeV3/datasetfiles/王亚林50/gangbi2qingdu/IV7L0391.JPG'
2020-05-06 10:31:19,097 - e:/桌面/app/work_project/Car_Engine/code/CarEngine/codeV3/mid_dir_operator.py[line:79] - ERROR: not file [Errno 13] Permission denied: 'e:/桌面/app/work_project/Car_Engine/code/CarEngine/codeV3/datasetfiles/王亚林50/gangbi2qingdu/IV7L0216.JPG'
2020-05-06 10:31:19,097 - e:/桌面/app/work_project/Car_Engine/code/CarEngine/codeV3/mid_dir_operator.py[line:79] - ERROR: not file [Errno 13] Permission denied: 'e:/桌面/app/work_project/Car_Engine/code/CarEngine/codeV3/datasetfiles/王亚林50/gangbi2qingdu/IV7L0027.JPG'
2020-05-06 10:31:19,108 - e:/桌面/app/work_project/Car_Engine/code/CarEngine/codeV3/mid_dir_operator.py[line:79] - ERROR: not file [Errno 13] Permission denied: 'e:/桌面/app/work_project/Car_Engine/code/CarEngine/codeV3/datasetfiles/王亚林50/gangbi1qingwei/'
2020-05-06 10:31:19,110 - e:/桌面/app/work_project/Car_Engine/code/CarEngine/codeV3/mid_dir_operator.py[line:79] - ERROR: not file [Errno 13] Permission denied: 'e:/桌面/app/work_project/Car_Engine/code/CarEngine/codeV3/datasetfiles/王亚林50/gangbi1qingwei/IV7L0144.JPG'
2020-05-06 10:31:19,112 - e:/桌面/app/work_project/Car_Engine/code/CarEngine/codeV3/mid_dir_operator.py[line:79] - ERROR: not file [Errno 13] Permission denied: 'e:/桌面/app/work_project/Car_Engine/code/CarEngine/codeV3/datasetfiles/王亚林50/gangbi1qingwei/IV000003.JPG'
2020-05-06 10:31:19,113 - e:/桌面/app/work_project/Car_Engine/code/CarEngine/codeV3/mid_dir_operator.py[line:79] - ERROR: not file [Errno 13] Permission denied: 'e:/桌面/app/work_project/Car_Engine/code/CarEngine/codeV3/datasetfiles/王亚林50/gangbi1qingwei/IV7L0169.JPG'
2020-05-06 10:31:19,114 - e:/桌面/app/work_project/Car_Engine/code/CarEngine/codeV3/mid_dir_operator.py[line:79] - ERROR: not file [Errno 13] Permission denied: 'e:/桌面/app/work_project/Car_Engine/code/CarEngine/codeV3/datasetfiles/王亚林50/gangbi1qingwei/IV000004 (3).JPG'
2020-05-06 10:31:19,123 - e:/桌面/app/work_project/Car_Engine/code/CarEngine/codeV3/mid_dir_operator.py[line:79] - ERROR: not file [Errno 13] Permission denied: 'e:/桌面/app/work_project/Car_Engine/code/CarEngine/codeV3/datasetfiles/王亚林50/gangbi1qingwei/IV7L0198 (2).JPG'
2020-05-06 10:32:30,839 - e:/桌面/app/work_project/Car_Engine/code/CarEngine/codeV3/mid_dir_operator.py[line:79] - ERROR: ^^^^^^^^^^^^^^^^^^^not file [Errno 13] Permission denied: 'e:/桌面/app/work_project/Car_Engine/code/CarEngine/codeV3/datasetfiles/王亚林50'
2020-05-06 10:32:30,840 - e:/桌面/app/work_project/Car_Engine/code/CarEngine/codeV3/mid_dir_operator.py[line:79] - ERROR: ^^^^^^^^^^^^^^^^^^^not file [Errno 13] Permission denied: 'e:/桌面/app/work_project/Car_Engine/code/CarEngine/codeV3/datasetfiles/王亚林50/gangbi3zhongdu/'
2020-05-06 10:32:30,841 - e:/桌面/app/work_project/Car_Engine/code/CarEngine/codeV3/mid_dir_operator.py[line:79] - ERROR: ^^^^^^^^^^^^^^^^^^^not file [Errno 13] Permission denied: 'e:/桌面/app/work_project/Car_Engine/code/CarEngine/codeV3/datasetfiles/王亚林50/gangbi3zhongdu/nEO_IMG_IV000261.JPG'
2020-05-06 10:32:30,841 - e:/桌面/app/work_project/Car_Engine/code/CarEngine/codeV3/mid_dir_operator.py[line:79] - ERROR: ^^^^^^^^^^^^^^^^^^^not file [Errno 13] Permission denied: 'e:/桌面/app/work_project/Car_Engine/code/CarEngine/codeV3/datasetfiles/王亚林50/gangbi3zhongdu/IV002120.JPG'
2020-05-06 10:32:30,844 - e:/桌面/app/work_project/Car_Engine/code/CarEngine/codeV3/mid_dir_operator.py[line:79] - ERROR: ^^^^^^^^^^^^^^^^^^^not file [Errno 13] Permission denied: 'e:/桌面/app/work_project/Car_Engine/code/CarEngine/codeV3/datasetfiles/王亚林50/gangbi3zhongdu/IV002180.JPG'
2020-05-06 10:32:30,846 - e:/桌面/app/work_project/Car_Engine/code/CarEngine/codeV3/mid_dir_operator.py[line:79] - ERROR: ^^^^^^^^^^^^^^^^^^^not file [Errno 13] Permission denied: 'e:/桌面/app/work_project/Car_Engine/code/CarEngine/codeV3/datasetfiles/王亚林50/gangbi3zhongdu/nEO_IMG_IV000322 (2).JPG'
2020-05-06 10:32:30,847 - e:/桌面/app/work_project/Car_Engine/code/CarEngine/codeV3/mid_dir_operator.py[line:79] - ERROR: ^^^^^^^^^^^^^^^^^^^not file [Errno 13] Permission denied: 'e:/桌面/app/work_project/Car_Engine/code/CarEngine/codeV3/datasetfiles/王亚林50/gangbi3zhongdu/IV002100.JPG'
2020-05-06 10:32:30,849 - e:/桌面/app/work_project/Car_Engine/code/CarEngine/codeV3/mid_dir_operator.py[line:79] - ERROR: ^^^^^^^^^^^^^^^^^^^not file [Errno 13] Permission denied: 'e:/桌面/app/work_project/Car_Engine/code/CarEngine/codeV3/datasetfiles/王亚林50/gangbi2qingdu/'
2020-05-06 10:32:30,851 - e:/桌面/app/work_project/Car_Engine/code/CarEngine/codeV3/mid_dir_operator.py[line:79] - ERROR: ^^^^^^^^^^^^^^^^^^^not file [Errno 13] Permission denied: 'e:/桌面/app/work_project/Car_Engine/code/CarEngine/codeV3/datasetfiles/王亚林50/gangbi2qingdu/IV7L0121 (3).JPG'
2020-05-06 10:32:30,852 - e:/桌面/app/work_project/Car_Engine/code/CarEngine/codeV3/mid_dir_operator.py[line:79] - ERROR: ^^^^^^^^^^^^^^^^^^^not file [Errno 13] Permission denied: 'e:/桌面/app/work_project/Car_Engine/code/CarEngine/codeV3/datasetfiles/王亚林50/gangbi2qingdu/IV7L0391.JPG'
2020-05-06 10:32:30,853 - e:/桌面/app/work_project/Car_Engine/code/CarEngine/codeV3/mid_dir_operator.py[line:79] - ERROR: ^^^^^^^^^^^^^^^^^^^not file [Errno 13] Permission denied: 'e:/桌面/app/work_project/Car_Engine/code/CarEngine/codeV3/datasetfiles/王亚林50/gangbi2qingdu/IV7L0216.JPG'
2020-05-06 10:32:30,854 - e:/桌面/app/work_project/Car_Engine/code/CarEngine/codeV3/mid_dir_operator.py[line:79] - ERROR: ^^^^^^^^^^^^^^^^^^^not file [Errno 13] Permission denied: 'e:/桌面/app/work_project/Car_Engine/code/CarEngine/codeV3/datasetfiles/王亚林50/gangbi2qingdu/IV7L0027.JPG'
2020-05-06 10:32:30,855 - e:/桌面/app/work_project/Car_Engine/code/CarEngine/codeV3/mid_dir_operator.py[line:79] - ERROR: ^^^^^^^^^^^^^^^^^^^not file [Errno 13] Permission denied: 'e:/桌面/app/work_project/Car_Engine/code/CarEngine/codeV3/datasetfiles/王亚林50/gangbi1qingwei/'
2020-05-06 10:32:30,856 - e:/桌面/app/work_project/Car_Engine/code/CarEngine/codeV3/mid_dir_operator.py[line:79] - ERROR: ^^^^^^^^^^^^^^^^^^^not file [Errno 13] Permission denied: 'e:/桌面/app/work_project/Car_Engine/code/CarEngine/codeV3/datasetfiles/王亚林50/gangbi1qingwei/IV7L0144.JPG'
2020-05-06 10:32:30,858 - e:/桌面/app/work_project/Car_Engine/code/CarEngine/codeV3/mid_dir_operator.py[line:79] - ERROR: ^^^^^^^^^^^^^^^^^^^not file [Errno 13] Permission denied: 'e:/桌面/app/work_project/Car_Engine/code/CarEngine/codeV3/datasetfiles/王亚林50/gangbi1qingwei/IV000003.JPG'
2020-05-06 10:32:30,870 - e:/桌面/app/work_project/Car_Engine/code/CarEngine/codeV3/mid_dir_operator.py[line:79] - ERROR: ^^^^^^^^^^^^^^^^^^^not file [Errno 13] Permission denied: 'e:/桌面/app/work_project/Car_Engine/code/CarEngine/codeV3/datasetfiles/王亚林50/gangbi1qingwei/IV7L0169.JPG'
2020-05-06 10:32:30,872 - e:/桌面/app/work_project/Car_Engine/code/CarEngine/codeV3/mid_dir_operator.py[line:79] - ERROR: ^^^^^^^^^^^^^^^^^^^not file [Errno 13] Permission denied: 'e:/桌面/app/work_project/Car_Engine/code/CarEngine/codeV3/datasetfiles/王亚林50/gangbi1qingwei/IV000004 (3).JPG'
2020-05-06 10:32:30,886 - e:/桌面/app/work_project/Car_Engine/code/CarEngine/codeV3/mid_dir_operator.py[line:79] - ERROR: ^^^^^^^^^^^^^^^^^^^not file [Errno 13] Permission denied: 'e:/桌面/app/work_project/Car_Engine/code/CarEngine/codeV3/datasetfiles/王亚林50/gangbi1qingwei/IV7L0198 (2).JPG'
2020-05-06 10:33:04,696 - e:/桌面/app/work_project/Car_Engine/code/CarEngine/codeV3/mid_dir_operator.py[line:79] - ERROR: ^^^^^^^^^^^^^^^^^^^not file [Errno 13] Permission denied: 'e:/桌面/app/work_project/Car_Engine/code/CarEngine/codeV3/datasetfiles/王亚林50'
2020-05-06 10:33:04,735 - e:/桌面/app/work_project/Car_Engine/code/CarEngine/codeV3/mid_dir_operator.py[line:79] - ERROR: ^^^^^^^^^^^^^^^^^^^not file [Errno 13] Permission denied: 'e:/桌面/app/work_project/Car_Engine/code/CarEngine/codeV3/datasetfiles/王亚林50/gangbi3zhongdu/'
2020-05-06 10:33:04,738 - e:/桌面/app/work_project/Car_Engine/code/CarEngine/codeV3/mid_dir_operator.py[line:79] - ERROR: ^^^^^^^^^^^^^^^^^^^not file [Errno 13] Permission denied: 'e:/桌面/app/work_project/Car_Engine/code/CarEngine/codeV3/datasetfiles/王亚林50/gangbi3zhongdu/nEO_IMG_IV000261.JPG'
2020-05-06 10:33:04,751 - e:/桌面/app/work_project/Car_Engine/code/CarEngine/codeV3/mid_dir_operator.py[line:79] - ERROR: ^^^^^^^^^^^^^^^^^^^not file [Errno 13] Permission denied: 'e:/桌面/app/work_project/Car_Engine/code/CarEngine/codeV3/datasetfiles/王亚林50/gangbi3zhongdu/IV002120.JPG'
2020-05-06 10:33:04,753 - e:/桌面/app/work_project/Car_Engine/code/CarEngine/codeV3/mid_dir_operator.py[line:79] - ERROR: ^^^^^^^^^^^^^^^^^^^not file [Errno 13] Permission denied: 'e:/桌面/app/work_project/Car_Engine/code/CarEngine/codeV3/datasetfiles/王亚林50/gangbi3zhongdu/IV002180.JPG'
2020-05-06 10:33:04,755 - e:/桌面/app/work_project/Car_Engine/code/CarEngine/codeV3/mid_dir_operator.py[line:79] - ERROR: ^^^^^^^^^^^^^^^^^^^not file [Errno 13] Permission denied: 'e:/桌面/app/work_project/Car_Engine/code/CarEngine/codeV3/datasetfiles/王亚林50/gangbi3zhongdu/nEO_IMG_IV000322 (2).JPG'
2020-05-06 10:33:04,756 - e:/桌面/app/work_project/Car_Engine/code/CarEngine/codeV3/mid_dir_operator.py[line:79] - ERROR: ^^^^^^^^^^^^^^^^^^^not file [Errno 13] Permission denied: 'e:/桌面/app/work_project/Car_Engine/code/CarEngine/codeV3/datasetfiles/王亚林50/gangbi3zhongdu/IV002100.JPG'
2020-05-06 10:33:04,769 - e:/桌面/app/work_project/Car_Engine/code/CarEngine/codeV3/mid_dir_operator.py[line:79] - ERROR: ^^^^^^^^^^^^^^^^^^^not file [Errno 13] Permission denied: 'e:/桌面/app/work_project/Car_Engine/code/CarEngine/codeV3/datasetfiles/王亚林50/gangbi2qingdu/'
2020-05-06 10:33:04,771 - e:/桌面/app/work_project/Car_Engine/code/CarEngine/codeV3/mid_dir_operator.py[line:79] - ERROR: ^^^^^^^^^^^^^^^^^^^not file [Errno 13] Permission denied: 'e:/桌面/app/work_project/Car_Engine/code/CarEngine/codeV3/datasetfiles/王亚林50/gangbi2qingdu/IV7L0121 (3).JPG'
2020-05-06 10:33:04,787 - e:/桌面/app/work_project/Car_Engine/code/CarEngine/codeV3/mid_dir_operator.py[line:79] - ERROR: ^^^^^^^^^^^^^^^^^^^not file [Errno 13] Permission denied: 'e:/桌面/app/work_project/Car_Engine/code/CarEngine/codeV3/datasetfiles/王亚林50/gangbi2qingdu/IV7L0391.JPG'
2020-05-06 10:33:04,798 - e:/桌面/app/work_project/Car_Engine/code/CarEngine/codeV3/mid_dir_operator.py[line:79] - ERROR: ^^^^^^^^^^^^^^^^^^^not file [Errno 13] Permission denied: 'e:/桌面/app/work_project/Car_Engine/code/CarEngine/codeV3/datasetfiles/王亚林50/gangbi2qingdu/IV7L0216.JPG'
2020-05-06 10:33:04,801 - e:/桌面/app/work_project/Car_Engine/code/CarEngine/codeV3/mid_dir_operator.py[line:79] - ERROR: ^^^^^^^^^^^^^^^^^^^not file [Errno 13] Permission denied: 'e:/桌面/app/work_project/Car_Engine/code/CarEngine/codeV3/datasetfiles/王亚林50/gangbi2qingdu/IV7L0027.JPG'
2020-05-06 10:33:04,803 - e:/桌面/app/work_project/Car_Engine/code/CarEngine/codeV3/mid_dir_operator.py[line:79] - ERROR: ^^^^^^^^^^^^^^^^^^^not file [Errno 13] Permission denied: 'e:/桌面/app/work_project/Car_Engine/code/CarEngine/codeV3/datasetfiles/王亚林50/gangbi1qingwei/'
2020-05-06 10:33:04,804 - e:/桌面/app/work_project/Car_Engine/code/CarEngine/codeV3/mid_dir_operator.py[line:79] - ERROR: ^^^^^^^^^^^^^^^^^^^not file [Errno 13] Permission denied: 'e:/桌面/app/work_project/Car_Engine/code/CarEngine/codeV3/datasetfiles/王亚林50/gangbi1qingwei/IV7L0144.JPG'
2020-05-06 10:33:04,806 - e:/桌面/app/work_project/Car_Engine/code/CarEngine/codeV3/mid_dir_operator.py[line:79] - ERROR: ^^^^^^^^^^^^^^^^^^^not file [Errno 13] Permission denied: 'e:/桌面/app/work_project/Car_Engine/code/CarEngine/codeV3/datasetfiles/王亚林50/gangbi1qingwei/IV000003.JPG'
2020-05-06 10:33:04,817 - e:/桌面/app/work_project/Car_Engine/code/CarEngine/codeV3/mid_dir_operator.py[line:79] - ERROR: ^^^^^^^^^^^^^^^^^^^not file [Errno 13] Permission denied: 'e:/桌面/app/work_project/Car_Engine/code/CarEngine/codeV3/datasetfiles/王亚林50/gangbi1qingwei/IV7L0169.JPG'
2020-05-06 10:33:04,821 - e:/桌面/app/work_project/Car_Engine/code/CarEngine/codeV3/mid_dir_operator.py[line:79] - ERROR: ^^^^^^^^^^^^^^^^^^^not file [Errno 13] Permission denied: 'e:/桌面/app/work_project/Car_Engine/code/CarEngine/codeV3/datasetfiles/王亚林50/gangbi1qingwei/IV000004 (3).JPG'
2020-05-06 10:33:04,833 - e:/桌面/app/work_project/Car_Engine/code/CarEngine/codeV3/mid_dir_operator.py[line:79] - ERROR: ^^^^^^^^^^^^^^^^^^^not file [Errno 13] Permission denied: 'e:/桌面/app/work_project/Car_Engine/code/CarEngine/codeV3/datasetfiles/王亚林50/gangbi1qingwei/IV7L0198 (2).JPG'
2020-05-06 11:09:09,792 - e:/桌面/app/work_project/Car_Engine/code/CarEngine/codeV3/mid_dir_operator.py[line:47] - ERROR: del file error:[WinError 267] The directory name is invalid: './datasetfiles/ddd.zip'
2020-05-06 11:37:05,834 - e:/桌面/app/work_project/Car_Engine/code/CarEngine/codeV3/mid_kafka_operate.py[line:60] - ERROR: kafka consumer error 
2020-05-06 11:37:30,809 - e:/桌面/app/work_project/Car_Engine/code/CarEngine/codeV3/mid_kafka_operate.py[line:60] - ERROR: kafka consumer error 
2020-05-06 11:38:34,553 - e:/桌面/app/work_project/Car_Engine/code/CarEngine/codeV3/mid_kafka_operate.py[line:60] - ERROR: kafka consumer error 
2020-05-06 11:40:54,498 - e:/桌面/app/work_project/Car_Engine/code/CarEngine/codeV3/mid_kafka_operate.py[line:60] - ERROR: kafka consumer error 
2020-05-06 11:44:37,172 - e:/桌面/app/work_project/Car_Engine/code/CarEngine/codeV3/mid_kafka_operate.py[line:60] - ERROR: kafka consumer error 
2020-05-06 11:45:00,048 - e:/桌面/app/work_project/Car_Engine/code/CarEngine/codeV3/mid_kafka_operate.py[line:60] - ERROR: kafka consumer error 
2020-05-06 11:46:03,789 - e:/桌面/app/work_project/Car_Engine/code/CarEngine/codeV3/mid_kafka_operate.py[line:61] - ERROR: kafka consumer error 
2020-05-06 11:46:19,377 - e:/桌面/app/work_project/Car_Engine/code/CarEngine/codeV3/mid_kafka_operate.py[line:61] - ERROR: kafka consumer error 
2020-05-06 11:46:37,453 - e:/桌面/app/work_project/Car_Engine/code/CarEngine/codeV3/mid_kafka_operate.py[line:61] - ERROR: kafka consumer error 
2020-05-06 12:43:43,696 - e:/桌面/app/work_project/Car_Engine/code/CarEngine/codeV3/mid_kafka_operate.py[line:60] - ERROR: kafka consumer error 
2020-05-06 12:43:54,833 - e:/桌面/app/work_project/Car_Engine/code/CarEngine/codeV3/mid_kafka_operate.py[line:60] - ERROR: kafka consumer error 
2020-05-06 12:44:55,553 - e:/桌面/app/work_project/Car_Engine/code/CarEngine/codeV3/mid_kafka_operate.py[line:61] - ERROR: kafka consumer error 
2020-05-06 12:45:01,232 - e:/桌面/app/work_project/Car_Engine/code/CarEngine/codeV3/mid_kafka_operate.py[line:61] - ERROR: kafka consumer error 
2020-05-06 13:22:46,579 - e:/桌面/app/work_project/Car_Engine/code/CarEngine/codeV3/mid_kafka_operate.py[line:61] - ERROR: kafka consumer error 
2020-05-06 13:24:29,490 - e:/桌面/app/work_project/Car_Engine/code/CarEngine/codeV3/mid_kafka_operate.py[line:61] - ERROR: kafka consumer error 
2020-05-06 13:24:53,010 - e:/桌面/app/work_project/Car_Engine/code/CarEngine/codeV3/mid_kafka_operate.py[line:61] - ERROR: kafka consumer error 
2020-05-06 13:25:40,630 - e:/桌面/app/work_project/Car_Engine/code/CarEngine/codeV3/mid_kafka_operate.py[line:61] - ERROR: kafka consumer error 
2020-05-06 13:27:28,031 - e:/桌面/app/work_project/Car_Engine/code/CarEngine/codeV3/mid_kafka_operate.py[line:61] - ERROR: kafka consumer error 
2020-05-06 13:28:54,084 - e:/桌面/app/work_project/Car_Engine/code/CarEngine/codeV3/mid_kafka_operate.py[line:63] - ERROR: kafka consumer error 
2020-05-06 13:31:03,314 - e:/桌面/app/work_project/Car_Engine/code/CarEngine/codeV3/mid_kafka_operate.py[line:63] - ERROR: kafka consumer error 
2020-05-06 13:35:30,543 - e:/桌面/app/work_project/Car_Engine/code/CarEngine/codeV3/mid_kafka_operate.py[line:62] - ERROR: kafka consumer error 
2020-05-06 13:35:58,282 - e:/桌面/app/work_project/Car_Engine/code/CarEngine/codeV3/mid_kafka_operate.py[line:63] - ERROR: kafka consumer error 
2020-05-06 13:36:45,924 - e:/桌面/app/work_project/Car_Engine/code/CarEngine/codeV3/mid_kafka_operate.py[line:63] - ERROR: kafka consumer error 
2020-05-06 13:37:55,235 - e:/桌面/app/work_project/Car_Engine/code/CarEngine/codeV3/mid_kafka_operate.py[line:63] - ERROR: kafka consumer error 
2020-05-06 13:37:56,522 - e:/桌面/app/work_project/Car_Engine/code/CarEngine/codeV3/mid_kafka_operate.py[line:63] - ERROR: kafka consumer error 
2020-05-06 13:40:31,508 - e:/桌面/app/work_project/Car_Engine/code/CarEngine/codeV3/mid_kafka_operate.py[line:63] - ERROR: kafka consumer error 
2020-05-06 13:40:32,950 - e:/桌面/app/work_project/Car_Engine/code/CarEngine/codeV3/mid_kafka_operate.py[line:63] - ERROR: kafka consumer error 
2020-05-06 13:41:48,080 - .\mid_kafka_operate.py[line:63] - ERROR: kafka consumer error 
2020-05-06 13:42:22,321 - .\mid_kafka_operate.py[line:63] - ERROR: kafka consumer error 
2020-05-06 13:42:23,036 - .\mid_kafka_operate.py[line:63] - ERROR: kafka consumer error 
2020-05-06 13:42:23,666 - .\mid_kafka_operate.py[line:63] - ERROR: kafka consumer error 
2020-05-06 13:42:23,986 - .\mid_kafka_operate.py[line:63] - ERROR: kafka consumer error 
2020-05-06 13:42:24,218 - .\mid_kafka_operate.py[line:63] - ERROR: kafka consumer error 
2020-05-06 13:42:24,418 - .\mid_kafka_operate.py[line:63] - ERROR: kafka consumer error 
2020-05-06 13:42:24,588 - .\mid_kafka_operate.py[line:63] - ERROR: kafka consumer error 
2020-05-06 13:42:24,803 - .\mid_kafka_operate.py[line:63] - ERROR: kafka consumer error 
2020-05-06 13:42:25,029 - .\mid_kafka_operate.py[line:63] - ERROR: kafka consumer error 
2020-05-06 13:42:25,210 - .\mid_kafka_operate.py[line:63] - ERROR: kafka consumer error 
2020-05-06 13:42:25,404 - .\mid_kafka_operate.py[line:63] - ERROR: kafka consumer error 
2020-05-06 13:42:25,588 - .\mid_kafka_operate.py[line:63] - ERROR: kafka consumer error 
2020-05-06 13:42:25,738 - .\mid_kafka_operate.py[line:63] - ERROR: kafka consumer error 
2020-05-06 13:42:25,892 - .\mid_kafka_operate.py[line:63] - ERROR: kafka consumer error 
2020-05-06 13:42:26,058 - .\mid_kafka_operate.py[line:63] - ERROR: kafka consumer error 
2020-05-06 13:42:26,361 - .\mid_kafka_operate.py[line:63] - ERROR: kafka consumer error 
2020-05-06 13:42:26,530 - .\mid_kafka_operate.py[line:63] - ERROR: kafka consumer error 
2020-05-06 13:42:26,683 - .\mid_kafka_operate.py[line:63] - ERROR: kafka consumer error 
2020-05-06 13:42:26,858 - .\mid_kafka_operate.py[line:63] - ERROR: kafka consumer error 
2020-05-06 13:42:29,193 - .\mid_kafka_operate.py[line:63] - ERROR: kafka consumer error 
2020-05-06 13:42:29,355 - .\mid_kafka_operate.py[line:63] - ERROR: kafka consumer error 
2020-05-06 13:42:29,522 - .\mid_kafka_operate.py[line:63] - ERROR: kafka consumer error 
2020-05-06 13:42:29,683 - .\mid_kafka_operate.py[line:63] - ERROR: kafka consumer error 
2020-05-06 13:42:29,834 - .\mid_kafka_operate.py[line:63] - ERROR: kafka consumer error 
2020-05-06 13:42:29,986 - .\mid_kafka_operate.py[line:63] - ERROR: kafka consumer error 
2020-05-06 13:42:30,146 - .\mid_kafka_operate.py[line:63] - ERROR: kafka consumer error 
2020-05-06 13:42:30,314 - .\mid_kafka_operate.py[line:63] - ERROR: kafka consumer error 
2020-05-06 13:42:30,843 - .\mid_kafka_operate.py[line:63] - ERROR: kafka consumer error 
2020-05-06 13:43:03,435 - .\mid_kafka_operate.py[line:63] - ERROR: kafka consumer error 
2020-05-06 13:43:06,769 - .\mid_kafka_operate.py[line:63] - ERROR: kafka consumer error 
2020-05-06 13:43:07,395 - .\mid_kafka_operate.py[line:63] - ERROR: kafka consumer error 
2020-05-06 13:43:07,918 - .\mid_kafka_operate.py[line:63] - ERROR: kafka consumer error 
2020-05-06 13:43:08,442 - .\mid_kafka_operate.py[line:63] - ERROR: kafka consumer error 
2020-05-06 13:43:08,860 - .\mid_kafka_operate.py[line:63] - ERROR: kafka consumer error 
2020-05-06 13:43:09,287 - .\mid_kafka_operate.py[line:63] - ERROR: kafka consumer error 
2020-05-06 13:43:09,702 - .\mid_kafka_operate.py[line:63] - ERROR: kafka consumer error 
2020-05-06 13:43:10,121 - .\mid_kafka_operate.py[line:63] - ERROR: kafka consumer error 
2020-05-06 13:43:10,426 - .\mid_kafka_operate.py[line:63] - ERROR: kafka consumer error 
2020-05-06 13:43:10,945 - .\mid_kafka_operate.py[line:63] - ERROR: kafka consumer error 
2020-05-06 13:43:11,375 - .\mid_kafka_operate.py[line:63] - ERROR: kafka consumer error 
2020-05-06 13:43:11,642 - .\mid_kafka_operate.py[line:63] - ERROR: kafka consumer error 
2020-05-06 13:43:11,937 - .\mid_kafka_operate.py[line:63] - ERROR: kafka consumer error 
2020-05-06 13:43:12,364 - .\mid_kafka_operate.py[line:63] - ERROR: kafka consumer error 
2020-05-06 13:43:12,579 - .\mid_kafka_operate.py[line:63] - ERROR: kafka consumer error 
2020-05-06 13:43:13,004 - .\mid_kafka_operate.py[line:63] - ERROR: kafka consumer error 
2020-05-06 13:43:13,308 - .\mid_kafka_operate.py[line:63] - ERROR: kafka consumer error 
2020-05-06 13:43:13,627 - .\mid_kafka_operate.py[line:63] - ERROR: kafka consumer error 
2020-05-06 13:43:14,066 - .\mid_kafka_operate.py[line:63] - ERROR: kafka consumer error 
2020-05-06 13:43:14,346 - .\mid_kafka_operate.py[line:63] - ERROR: kafka consumer error 
2020-05-06 13:43:14,779 - .\mid_kafka_operate.py[line:63] - ERROR: kafka consumer error 
2020-05-06 13:43:15,002 - .\mid_kafka_operate.py[line:63] - ERROR: kafka consumer error 
2020-05-06 13:43:15,433 - .\mid_kafka_operate.py[line:63] - ERROR: kafka consumer error 
2020-05-06 13:43:15,698 - .\mid_kafka_operate.py[line:63] - ERROR: kafka consumer error 
2020-05-06 13:43:16,127 - .\mid_kafka_operate.py[line:63] - ERROR: kafka consumer error 
2020-05-06 13:43:16,410 - .\mid_kafka_operate.py[line:63] - ERROR: kafka consumer error 
2020-05-06 13:43:16,844 - .\mid_kafka_operate.py[line:63] - ERROR: kafka consumer error 
2020-05-06 13:43:17,275 - .\mid_kafka_operate.py[line:63] - ERROR: kafka consumer error 
2020-05-06 13:43:17,473 - .\mid_kafka_operate.py[line:63] - ERROR: kafka consumer error 
2020-05-06 13:43:17,714 - .\mid_kafka_operate.py[line:63] - ERROR: kafka consumer error 
2020-05-06 13:43:18,246 - .\mid_kafka_operate.py[line:63] - ERROR: kafka consumer error 
2020-05-06 13:53:13,110 - e:/桌面/app/work_project/Car_Engine/code/CarEngine/codeV3/mid_kafka_operate.py[line:62] - ERROR: kafka consumer error 
2020-05-06 13:54:21,860 - e:/桌面/app/work_project/Car_Engine/code/CarEngine/codeV3/mid_kafka_operate.py[line:62] - ERROR: kafka consumer error 
2020-05-06 13:55:34,572 - .\mid_kafka_operate.py[line:62] - ERROR: kafka consumer error 
2020-05-06 14:24:29,417 - e:/桌面/app/work_project/Car_Engine/code/CarEngine/codeV3/mid_kafka_operate.py[line:63] - ERROR: kafka consumer error 
2020-05-06 14:24:30,303 - e:/桌面/app/work_project/Car_Engine/code/CarEngine/codeV3/mid_kafka_operate.py[line:63] - ERROR: kafka consumer error 
2020-05-06 14:24:31,047 - e:/桌面/app/work_project/Car_Engine/code/CarEngine/codeV3/mid_kafka_operate.py[line:63] - ERROR: kafka consumer error 
2020-05-06 14:24:31,395 - e:/桌面/app/work_project/Car_Engine/code/CarEngine/codeV3/mid_kafka_operate.py[line:63] - ERROR: kafka consumer error 
2020-05-07 11:21:16,827 - e:/桌面/app/work_project/Car_Engine/code/CarEngine/codeV3/mid_database_operate.py[line:55] - ERROR: list index out of range model:3 info get error
2020-05-07 14:08:15,168 - e:/桌面/app/work_project/Car_Engine/code/CarEngine/codeV3/mid_run.py[line:53] - ERROR: File address acquisition failed
2020-05-08 10:26:31,479 - E:\桌面\app\work_project\Car_Engine\code\CarEngine\codeV3\mid_run.py[line:61] - ERROR: 'training_statu'
2020-05-08 10:26:31,503 - E:\桌面\app\work_project\Car_Engine\code\CarEngine\codeV3\mid_run.py[line:61] - ERROR: 'training_statu'
2020-05-08 10:26:31,520 - E:\桌面\app\work_project\Car_Engine\code\CarEngine\codeV3\mid_run.py[line:61] - ERROR: 'training_statu'
2020-05-08 10:26:35,530 - E:\桌面\app\work_project\Car_Engine\code\CarEngine\codeV3\mid_run.py[line:61] - ERROR: 'training_statu'
2020-05-08 10:26:35,534 - E:\桌面\app\work_project\Car_Engine\code\CarEngine\codeV3\mid_run.py[line:61] - ERROR: 'training_statu'
2020-05-08 10:26:35,536 - E:\桌面\app\work_project\Car_Engine\code\CarEngine\codeV3\mid_run.py[line:61] - ERROR: 'training_statu'
2020-05-08 10:26:39,560 - E:\桌面\app\work_project\Car_Engine\code\CarEngine\codeV3\mid_run.py[line:61] - ERROR: 'training_statu'
2020-05-08 10:26:39,582 - E:\桌面\app\work_project\Car_Engine\code\CarEngine\codeV3\mid_run.py[line:61] - ERROR: 'training_statu'
2020-05-08 10:26:39,600 - E:\桌面\app\work_project\Car_Engine\code\CarEngine\codeV3\mid_run.py[line:61] - ERROR: 'training_statu'
2020-05-08 10:27:41,608 - E:\桌面\app\work_project\Car_Engine\code\CarEngine\codeV3\mid_run.py[line:59] - ERROR: 'Master' object has no attribute 'u_data'
2020-05-08 10:27:41,611 - E:\桌面\app\work_project\Car_Engine\code\CarEngine\codeV3\mid_run.py[line:59] - ERROR: 'Master' object has no attribute 'u_data'
2020-05-08 10:27:41,614 - E:\桌面\app\work_project\Car_Engine\code\CarEngine\codeV3\mid_run.py[line:59] - ERROR: 'Master' object has no attribute 'u_data'
2020-05-08 10:27:45,628 - E:\桌面\app\work_project\Car_Engine\code\CarEngine\codeV3\mid_run.py[line:59] - ERROR: 'Master' object has no attribute 'u_data'
2020-05-08 10:27:45,632 - E:\桌面\app\work_project\Car_Engine\code\CarEngine\codeV3\mid_run.py[line:59] - ERROR: 'Master' object has no attribute 'u_data'
2020-05-08 10:27:45,635 - E:\桌面\app\work_project\Car_Engine\code\CarEngine\codeV3\mid_run.py[line:59] - ERROR: 'Master' object has no attribute 'u_data'
2020-05-08 10:30:05,941 - E:\桌面\app\work_project\Car_Engine\code\CarEngine\codeV3\mid_run.py[line:59] - ERROR: 'Master' object has no attribute 'u_data'
2020-05-08 10:30:05,962 - E:\桌面\app\work_project\Car_Engine\code\CarEngine\codeV3\mid_run.py[line:59] - ERROR: 'Master' object has no attribute 'u_data'
2020-05-08 10:30:05,971 - E:\桌面\app\work_project\Car_Engine\code\CarEngine\codeV3\mid_run.py[line:59] - ERROR: 'Master' object has no attribute 'u_data'
2020-05-08 10:31:58,781 - E:\桌面\app\work_project\Car_Engine\code\CarEngine\codeV3\mid_run.py[line:60] - ERROR: 'Master' object has no attribute 'u_data'
2020-05-08 10:31:58,793 - E:\桌面\app\work_project\Car_Engine\code\CarEngine\codeV3\mid_run.py[line:60] - ERROR: 'Master' object has no attribute 'u_data'
2020-05-08 10:31:58,804 - E:\桌面\app\work_project\Car_Engine\code\CarEngine\codeV3\mid_run.py[line:60] - ERROR: 'Master' object has no attribute 'u_data'
2020-05-08 10:32:54,048 - E:\桌面\app\work_project\Car_Engine\code\CarEngine\codeV3\mid_run.py[line:60] - ERROR: 'Master' object has no attribute 'u_data'
2020-05-08 10:32:54,064 - E:\桌面\app\work_project\Car_Engine\code\CarEngine\codeV3\mid_run.py[line:60] - ERROR: 'Master' object has no attribute 'u_data'
2020-05-08 10:32:54,078 - E:\桌面\app\work_project\Car_Engine\code\CarEngine\codeV3\mid_run.py[line:60] - ERROR: 'Master' object has no attribute 'u_data'
2020-05-08 10:34:10,931 - E:\桌面\app\work_project\Car_Engine\code\CarEngine\codeV3\mid_run.py[line:60] - ERROR: 'Master' object has no attribute 'u_data'
2020-05-08 10:34:10,943 - E:\桌面\app\work_project\Car_Engine\code\CarEngine\codeV3\mid_run.py[line:60] - ERROR: 'Master' object has no attribute 'u_data'
2020-05-08 10:34:10,951 - E:\桌面\app\work_project\Car_Engine\code\CarEngine\codeV3\mid_run.py[line:60] - ERROR: 'Master' object has no attribute 'u_data'
2020-05-08 10:34:44,810 - E:\桌面\app\work_project\Car_Engine\code\CarEngine\codeV3\mid_run.py[line:60] - ERROR: File is not a zip file
2020-05-08 10:34:45,607 - E:\桌面\app\work_project\Car_Engine\code\CarEngine\codeV3\mid_run.py[line:60] - ERROR: File is not a zip file
2020-05-08 10:45:06,585 - E:\桌面\app\work_project\Car_Engine\code\CarEngine\codeV3\mid_run.py[line:61] - ERROR: 'bool' object is not subscriptable
2020-05-08 10:45:08,145 - E:\桌面\app\work_project\Car_Engine\code\CarEngine\codeV3\mid_run.py[line:61] - ERROR: 'task_type'
2020-05-08 10:45:09,184 - E:\桌面\app\work_project\Car_Engine\code\CarEngine\codeV3\mid_run.py[line:61] - ERROR: 'task_type'
2020-05-08 10:45:14,309 - E:\桌面\app\work_project\Car_Engine\code\CarEngine\codeV3\mid_run.py[line:61] - ERROR: 'bool' object is not subscriptable
2020-05-08 10:45:15,403 - E:\桌面\app\work_project\Car_Engine\code\CarEngine\codeV3\mid_run.py[line:61] - ERROR: 'task_type'
2020-05-08 10:45:16,742 - E:\桌面\app\work_project\Car_Engine\code\CarEngine\codeV3\mid_run.py[line:61] - ERROR: 'task_type'
2020-05-08 10:45:21,487 - E:\桌面\app\work_project\Car_Engine\code\CarEngine\codeV3\mid_run.py[line:61] - ERROR: 'bool' object is not subscriptable
2020-05-08 10:45:22,323 - E:\桌面\app\work_project\Car_Engine\code\CarEngine\codeV3\mid_run.py[line:61] - ERROR: 'task_type'
2020-05-08 10:48:25,145 - E:\桌面\app\work_project\Car_Engine\code\CarEngine\codeV3\mid_run.py[line:61] - ERROR: 'bool' object is not subscriptable
2020-05-08 10:48:26,544 - E:\桌面\app\work_project\Car_Engine\code\CarEngine\codeV3\mid_run.py[line:61] - ERROR: 'task_type'
2020-05-08 10:49:02,861 - E:\桌面\app\work_project\Car_Engine\code\CarEngine\codeV3\mid_run.py[line:62] - ERROR: 'bool' object is not subscriptable
2020-05-08 10:50:06,852 - E:\桌面\app\work_project\Car_Engine\code\CarEngine\codeV3\mid_run.py[line:62] - ERROR: 'bool' object is not subscriptable
2020-05-08 10:50:08,276 - E:\桌面\app\work_project\Car_Engine\code\CarEngine\codeV3\mid_run.py[line:62] - ERROR: 'task_type'
2020-05-08 10:50:09,258 - E:\桌面\app\work_project\Car_Engine\code\CarEngine\codeV3\mid_run.py[line:62] - ERROR: 'task_type'
2020-05-08 11:06:55,459 - e:\桌面\app\work_project\Car_Engine\code\CarEngine\codeV3\mid_run.py[line:63] - ERROR: 'bool' object is not subscriptable
2020-05-08 11:06:56,834 - e:\桌面\app\work_project\Car_Engine\code\CarEngine\codeV3\mid_run.py[line:63] - ERROR: 'task_type'
2020-05-08 11:06:58,664 - e:\桌面\app\work_project\Car_Engine\code\CarEngine\codeV3\mid_run.py[line:63] - ERROR: 'task_type'
2020-05-08 11:07:04,174 - e:\桌面\app\work_project\Car_Engine\code\CarEngine\codeV3\mid_run.py[line:63] - ERROR: 'bool' object is not subscriptable
2020-05-08 11:07:05,797 - e:\桌面\app\work_project\Car_Engine\code\CarEngine\codeV3\mid_run.py[line:63] - ERROR: 'task_type'
2020-05-08 11:07:07,551 - e:\桌面\app\work_project\Car_Engine\code\CarEngine\codeV3\mid_run.py[line:63] - ERROR: 'task_type'
2020-05-08 11:07:24,930 - e:\桌面\app\work_project\Car_Engine\code\CarEngine\codeV3\mid_run.py[line:63] - ERROR: 'bool' object is not subscriptable
2020-05-08 11:07:26,374 - e:\桌面\app\work_project\Car_Engine\code\CarEngine\codeV3\mid_run.py[line:63] - ERROR: 'task_type'
2020-05-08 11:07:27,840 - e:\桌面\app\work_project\Car_Engine\code\CarEngine\codeV3\mid_run.py[line:63] - ERROR: 'task_type'
2020-05-08 11:36:50,832 - e:\桌面\app\work_project\Car_Engine\code\CarEngine\codeV3\mid_run.py[line:63] - ERROR: 'model_version'
2020-05-08 11:39:03,569 - e:\桌面\app\work_project\Car_Engine\code\CarEngine\codeV3\mid_run.py[line:63] - ERROR: 'model_version'
2020-05-08 11:41:41,746 - e:\桌面\app\work_project\Car_Engine\code\CarEngine\codeV3\mid_run.py[line:63] - ERROR: 'model_version'
2020-05-08 11:41:44,278 - e:\桌面\app\work_project\Car_Engine\code\CarEngine\codeV3\mid_run.py[line:63] - ERROR: 'task_type'
2020-05-08 11:41:46,257 - e:\桌面\app\work_project\Car_Engine\code\CarEngine\codeV3\mid_run.py[line:63] - ERROR: 'task_type'
2020-05-08 14:41:40,721 - E:\桌面\app\work_project\Car_Engine\code\CarEngine\codeV3\mid_run.py[line:63] - ERROR: 'model_version'
2020-05-08 14:48:44,721 - e:\桌面\app\work_project\Car_Engine\code\CarEngine\codeV3\mid_run.py[line:63] - ERROR: 'model_version'
2020-05-08 14:48:46,275 - e:\桌面\app\work_project\Car_Engine\code\CarEngine\codeV3\mid_run.py[line:63] - ERROR: 'task_type'
2020-05-08 14:49:33,129 - e:\桌面\app\work_project\Car_Engine\code\CarEngine\codeV3\mid_run.py[line:63] - ERROR: 'model_version'
2020-05-08 14:53:43,515 - e:\桌面\app\work_project\Car_Engine\code\CarEngine\codeV3\mid_run.py[line:63] - ERROR: 'NoneType' object has no attribute 'model_fileaddr'
2020-05-08 14:53:45,004 - e:\桌面\app\work_project\Car_Engine\code\CarEngine\codeV3\mid_run.py[line:63] - ERROR: 'task_type'
2020-05-08 14:53:45,967 - e:\桌面\app\work_project\Car_Engine\code\CarEngine\codeV3\mid_run.py[line:63] - ERROR: 'task_type'
2020-05-08 14:53:56,830 - e:\桌面\app\work_project\Car_Engine\code\CarEngine\codeV3\mid_run.py[line:63] - ERROR: 'NoneType' object has no attribute 'model_fileaddr'
2020-05-08 14:53:58,320 - e:\桌面\app\work_project\Car_Engine\code\CarEngine\codeV3\mid_run.py[line:63] - ERROR: 'task_type'
2020-05-08 14:53:59,842 - e:\桌面\app\work_project\Car_Engine\code\CarEngine\codeV3\mid_run.py[line:63] - ERROR: 'task_type'
2020-05-08 14:54:05,159 - e:\桌面\app\work_project\Car_Engine\code\CarEngine\codeV3\mid_run.py[line:63] - ERROR: 'NoneType' object has no attribute 'model_fileaddr'
2020-05-08 14:59:31,669 - e:\桌面\app\work_project\Car_Engine\code\CarEngine\codeV3\mid_run.py[line:62] - ERROR: 'NoneType' object has no attribute 'model_fileaddr'
2020-05-08 15:00:59,839 - e:\桌面\app\work_project\Car_Engine\code\CarEngine\codeV3\mid_run.py[line:62] - ERROR: 'task_type'
2020-05-08 15:01:13,576 - e:\桌面\app\work_project\Car_Engine\code\CarEngine\codeV3\mid_run.py[line:62] - ERROR: 'task_type'
2020-05-08 15:01:48,425 - e:\桌面\app\work_project\Car_Engine\code\CarEngine\codeV3\mid_run.py[line:62] - ERROR: 'NoneType' object has no attribute 'model_fileaddr'
2020-05-08 15:04:53,452 - e:\桌面\app\work_project\Car_Engine\code\CarEngine\codeV3\mid_run.py[line:62] - ERROR: 'task_type'
2020-05-08 15:05:36,222 - e:\桌面\app\work_project\Car_Engine\code\CarEngine\codeV3\mid_run.py[line:62] - ERROR: 'task_type'
2020-05-08 15:06:47,204 - e:\桌面\app\work_project\Car_Engine\code\CarEngine\codeV3\mid_run.py[line:62] - ERROR: HTTPConnectionPool(host='172.16.0.44', port=9999): Max retries exceeded with url: /api/datasets/download?dataset_id=2 (Caused by NewConnectionError('<urllib3.connection.HTTPConnection object at 0x000002AE5A1BDF98>: Failed to establish a new connection: [WinError 10061] No connection could be made because the target machine actively refused it',))
2020-05-08 15:06:49,393 - e:\桌面\app\work_project\Car_Engine\code\CarEngine\codeV3\mid_run.py[line:62] - ERROR: HTTPConnectionPool(host='172.16.0.44', port=9999): Max retries exceeded with url: /api/datasets/download?dataset_id=2 (Caused by NewConnectionError('<urllib3.connection.HTTPConnection object at 0x000002AE5A1EEF60>: Failed to establish a new connection: [WinError 10061] No connection could be made because the target machine actively refused it',))
2020-05-08 15:06:51,647 - e:\桌面\app\work_project\Car_Engine\code\CarEngine\codeV3\mid_run.py[line:62] - ERROR: HTTPConnectionPool(host='172.16.0.44', port=9999): Max retries exceeded with url: /api/datasets/download?dataset_id=2 (Caused by NewConnectionError('<urllib3.connection.HTTPConnection object at 0x000002AE5A2094A8>: Failed to establish a new connection: [WinError 10061] No connection could be made because the target machine actively refused it',))
2020-05-08 15:06:57,958 - e:\桌面\app\work_project\Car_Engine\code\CarEngine\codeV3\mid_run.py[line:62] - ERROR: HTTPConnectionPool(host='172.16.0.44', port=9999): Max retries exceeded with url: /api/datasets/download?dataset_id=2 (Caused by NewConnectionError('<urllib3.connection.HTTPConnection object at 0x000002AE5A168240>: Failed to establish a new connection: [WinError 10061] No connection could be made because the target machine actively refused it',))
2020-05-08 15:07:00,219 - e:\桌面\app\work_project\Car_Engine\code\CarEngine\codeV3\mid_run.py[line:62] - ERROR: HTTPConnectionPool(host='172.16.0.44', port=9999): Max retries exceeded with url: /api/datasets/download?dataset_id=2 (Caused by NewConnectionError('<urllib3.connection.HTTPConnection object at 0x000002AE5A211208>: Failed to establish a new connection: [WinError 10061] No connection could be made because the target machine actively refused it',))
2020-05-08 15:08:10,843 - e:\桌面\app\work_project\Car_Engine\code\CarEngine\codeV3\mid_run.py[line:63] - ERROR: HTTPConnectionPool(host='172.16.0.44', port=9999): Max retries exceeded with url: /api/datasets/download?dataset_id=2 (Caused by NewConnectionError('<urllib3.connection.HTTPConnection object at 0x00000253171CDF98>: Failed to establish a new connection: [WinError 10061] No connection could be made because the target machine actively refused it',))
2020-05-08 15:08:13,087 - e:\桌面\app\work_project\Car_Engine\code\CarEngine\codeV3\mid_run.py[line:63] - ERROR: HTTPConnectionPool(host='172.16.0.44', port=9999): Max retries exceeded with url: /api/datasets/download?dataset_id=2 (Caused by NewConnectionError('<urllib3.connection.HTTPConnection object at 0x00000253171FEF60>: Failed to establish a new connection: [WinError 10061] No connection could be made because the target machine actively refused it',))
2020-05-08 15:08:15,340 - e:\桌面\app\work_project\Car_Engine\code\CarEngine\codeV3\mid_run.py[line:63] - ERROR: HTTPConnectionPool(host='172.16.0.44', port=9999): Max retries exceeded with url: /api/datasets/download?dataset_id=2 (Caused by NewConnectionError('<urllib3.connection.HTTPConnection object at 0x00000253172194A8>: Failed to establish a new connection: [WinError 10061] No connection could be made because the target machine actively refused it',))
2020-05-08 15:16:42,401 - e:\桌面\app\work_project\Car_Engine\code\CarEngine\codeV3\mid_run.py[line:63] - ERROR: HTTPConnectionPool(host='172.16.0.44', port=9999): Max retries exceeded with url: /api/datasets/download?dataset_id=2 (Caused by NewConnectionError('<urllib3.connection.HTTPConnection object at 0x000001BC1B4DC320>: Failed to establish a new connection: [WinError 10061] No connection could be made because the target machine actively refused it',))
2020-05-08 15:16:44,756 - e:\桌面\app\work_project\Car_Engine\code\CarEngine\codeV3\mid_run.py[line:63] - ERROR: HTTPConnectionPool(host='172.16.0.44', port=9999): Max retries exceeded with url: /api/datasets/download?dataset_id=2 (Caused by NewConnectionError('<urllib3.connection.HTTPConnection object at 0x000001BC1B54CC88>: Failed to establish a new connection: [WinError 10061] No connection could be made because the target machine actively refused it',))
2020-05-08 15:16:46,997 - e:\桌面\app\work_project\Car_Engine\code\CarEngine\codeV3\mid_run.py[line:63] - ERROR: HTTPConnectionPool(host='172.16.0.44', port=9999): Max retries exceeded with url: /api/datasets/download?dataset_id=2 (Caused by NewConnectionError('<urllib3.connection.HTTPConnection object at 0x000001BC1B4BC8D0>: Failed to establish a new connection: [WinError 10061] No connection could be made because the target machine actively refused it',))
2020-05-08 15:22:39,286 - e:\桌面\app\work_project\Car_Engine\code\CarEngine\codeV3\mid_run.py[line:63] - ERROR: 'NoneType' object has no attribute 'model_fileaddr'
2020-05-08 15:22:39,624 - e:\桌面\app\work_project\Car_Engine\code\CarEngine\codeV3\mid_database_operate.py[line:92] - ERROR: model info get error 'NoneType' object has no attribute 'model_status'
2020-05-08 15:22:39,625 - e:\桌面\app\work_project\Car_Engine\code\CarEngine\codeV3\mid_run.py[line:116] - ERROR: init opt result save error 2020-05-08 09:32:38
2020-05-08 15:22:39,625 - e:\桌面\app\work_project\Car_Engine\code\CarEngine\codeV3\mid_run.py[line:63] - ERROR: 'train_model_id'
2020-05-08 15:22:39,982 - e:\桌面\app\work_project\Car_Engine\code\CarEngine\codeV3\mid_run.py[line:63] - ERROR: 'NoneType' object has no attribute 'model_status'
2020-05-08 15:22:44,192 - e:\桌面\app\work_project\Car_Engine\code\CarEngine\codeV3\mid_run.py[line:63] - ERROR: 'NoneType' object has no attribute 'model_fileaddr'
2020-05-08 15:23:43,510 - e:\桌面\app\work_project\Car_Engine\code\CarEngine\codeV3\mid_run.py[line:63] - ERROR: 'NoneType' object has no attribute 'model_fileaddr'
2020-05-08 15:25:53,971 - e:\桌面\app\work_project\Car_Engine\code\CarEngine\codeV3\mid_run.py[line:52] - ERROR: Abnormal end of training id 2020-05-08 09:31:37
2020-05-08 15:25:57,979 - e:\桌面\app\work_project\Car_Engine\code\CarEngine\codeV3\mid_run.py[line:63] - ERROR: malformed node or string: <_ast.Name object at 0x0000016811B3D438>
2020-05-08 15:25:58,247 - e:\桌面\app\work_project\Car_Engine\code\CarEngine\codeV3\mid_database_operate.py[line:92] - ERROR: model info get error 'NoneType' object has no attribute 'model_status'
2020-05-08 15:25:58,248 - e:\桌面\app\work_project\Car_Engine\code\CarEngine\codeV3\mid_run.py[line:116] - ERROR: init opt result save error 2020-05-08 09:32:38
2020-05-08 15:25:58,248 - e:\桌面\app\work_project\Car_Engine\code\CarEngine\codeV3\mid_run.py[line:63] - ERROR: 'train_model_id'
2020-05-08 15:25:58,557 - e:\桌面\app\work_project\Car_Engine\code\CarEngine\codeV3\mid_run.py[line:63] - ERROR: 'NoneType' object has no attribute 'model_status'
2020-05-08 15:35:24,681 - e:\桌面\app\work_project\Car_Engine\code\CarEngine\codeV3\mid_run.py[line:63] - ERROR: malformed node or string: <_ast.Name object at 0x000001C12DAD65C0>
2020-05-08 15:36:29,556 - e:\桌面\app\work_project\Car_Engine\code\CarEngine\codeV3\mid_run.py[line:63] - ERROR: malformed node or string: <_ast.Name object at 0x000002723DDA8F28>
2020-05-08 15:57:24,870 - e:\桌面\app\work_project\Car_Engine\code\CarEngine\codeV3\mid_run.py[line:63] - ERROR: 'training_status'
2020-05-08 15:57:24,888 - e:\桌面\app\work_project\Car_Engine\code\CarEngine\codeV3\mid_run.py[line:63] - ERROR: 'training_status'
2020-05-08 15:57:24,915 - e:\桌面\app\work_project\Car_Engine\code\CarEngine\codeV3\mid_run.py[line:63] - ERROR: 'training_status'
2020-05-08 15:57:28,926 - e:\桌面\app\work_project\Car_Engine\code\CarEngine\codeV3\mid_run.py[line:63] - ERROR: 'training_status'
2020-05-08 15:57:28,934 - e:\桌面\app\work_project\Car_Engine\code\CarEngine\codeV3\mid_run.py[line:63] - ERROR: 'training_status'
2020-05-08 15:57:28,940 - e:\桌面\app\work_project\Car_Engine\code\CarEngine\codeV3\mid_run.py[line:63] - ERROR: 'training_status'
2020-05-08 16:01:06,733 - e:\桌面\app\work_project\Car_Engine\code\CarEngine\codeV3\mid_database_operate.py[line:92] - ERROR: model info get error 'NoneType' object has no attribute 'model_status'
2020-05-08 16:01:06,734 - e:\桌面\app\work_project\Car_Engine\code\CarEngine\codeV3\mid_run.py[line:109] - ERROR: init opt result save error 1111-05-07 15:43:54.152928
2020-05-08 16:01:06,746 - e:\桌面\app\work_project\Car_Engine\code\CarEngine\codeV3\mid_run.py[line:56] - ERROR: 'train_model_id'
2020-05-08 16:01:07,430 - e:\桌面\app\work_project\Car_Engine\code\CarEngine\codeV3\mid_run.py[line:45] - ERROR: Abnormal end of training id 0000-05-07 15:43:54.152928
2020-05-08 16:19:34,620 - e:\桌面\app\work_project\Car_Engine\code\CarEngine\codeV3\mid_run.py[line:56] - ERROR: 'training_model_id'
2020-05-08 16:19:34,630 - e:\桌面\app\work_project\Car_Engine\code\CarEngine\codeV3\mid_run.py[line:56] - ERROR: malformed node or string: <_ast.Name object at 0x000001AB8F0716A0>
2020-05-08 16:19:35,021 - e:\桌面\app\work_project\Car_Engine\code\CarEngine\codeV3\mid_run.py[line:56] - ERROR: 'NoneType' object has no attribute 'model_status'
2020-05-08 16:25:39,371 - e:\桌面\app\work_project\Car_Engine\code\CarEngine\codeV3\mid_run.py[line:56] - ERROR: 'training_model_id'
2020-05-08 16:25:57,437 - e:\桌面\app\work_project\Car_Engine\code\CarEngine\codeV3\mid_dir_operator.py[line:90] - ERROR: dataset path get fail [WinError 3] The system cannot find the path specified: './datasetfiles'
2020-05-08 16:25:57,438 - e:\桌面\app\work_project\Car_Engine\code\CarEngine\codeV3\mid_run.py[line:80] - ERROR: File address acquisition failed
2020-05-08 16:25:57,439 - e:\桌面\app\work_project\Car_Engine\code\CarEngine\codeV3\mid_run.py[line:56] - ERROR: 'bool' object is not subscriptable
2020-05-08 16:25:57,461 - e:\桌面\app\work_project\Car_Engine\code\CarEngine\codeV3\mid_run.py[line:56] - ERROR: malformed node or string: <_ast.Name object at 0x0000027D4E1ED438>
2020-05-08 16:25:57,716 - e:\桌面\app\work_project\Car_Engine\code\CarEngine\codeV3\mid_dir_operator.py[line:90] - ERROR: dataset path get fail [WinError 3] The system cannot find the path specified: './datasetfiles'
2020-05-08 16:25:57,717 - e:\桌面\app\work_project\Car_Engine\code\CarEngine\codeV3\mid_run.py[line:80] - ERROR: File address acquisition failed
2020-05-08 16:25:57,718 - e:\桌面\app\work_project\Car_Engine\code\CarEngine\codeV3\mid_run.py[line:56] - ERROR: 'bool' object is not subscriptable
2020-05-08 16:29:01,815 - e:\桌面\app\work_project\Car_Engine\code\CarEngine\codeV3\mid_run.py[line:56] - ERROR: [Errno 2] No such file or directory: './datasetfiles/3.zip'
2020-05-08 16:29:01,827 - e:\桌面\app\work_project\Car_Engine\code\CarEngine\codeV3\mid_run.py[line:56] - ERROR: malformed node or string: <_ast.Name object at 0x000002B287CBE5C0>
2020-05-08 16:29:02,214 - e:\桌面\app\work_project\Car_Engine\code\CarEngine\codeV3\mid_run.py[line:56] - ERROR: [Errno 2] No such file or directory: './datasetfiles/3.zip'
2020-05-08 16:29:51,596 - e:\桌面\app\work_project\Car_Engine\code\CarEngine\codeV3\mid_run.py[line:56] - ERROR: [Errno 2] No such file or directory: './datasetfiles/3.zip'
2020-05-08 16:29:51,615 - e:\桌面\app\work_project\Car_Engine\code\CarEngine\codeV3\mid_run.py[line:56] - ERROR: malformed node or string: <_ast.Name object at 0x00000204E610C5C0>
2020-05-08 16:29:51,989 - e:\桌面\app\work_project\Car_Engine\code\CarEngine\codeV3\mid_run.py[line:56] - ERROR: [Errno 2] No such file or directory: './datasetfiles/3.zip'
2020-05-08 16:39:08,823 - e:\桌面\app\work_project\Car_Engine\code\CarEngine\codeV3\mid_run.py[line:56] - ERROR: [Errno 2] No such file or directory: './datasetfiles/3.zip'
2020-05-08 16:39:13,544 - e:\桌面\app\work_project\Car_Engine\code\CarEngine\codeV3\mid_run.py[line:56] - ERROR: malformed node or string: <_ast.Name object at 0x00000187BA26A780>
2020-05-08 16:39:21,642 - e:\桌面\app\work_project\Car_Engine\code\CarEngine\codeV3\mid_run.py[line:56] - ERROR: [Errno 2] No such file or directory: './datasetfiles/3.zip'
2020-05-08 16:50:07,076 - e:\桌面\app\work_project\Car_Engine\code\CarEngine\codeV3\mid_run.py[line:58] - ERROR: malformed node or string: <_ast.Name object at 0x000001988A1B5048>
2020-05-08 16:50:11,117 - e:\桌面\app\work_project\Car_Engine\code\CarEngine\codeV3\mid_run.py[line:58] - ERROR: malformed node or string: <_ast.Name object at 0x000001988A1B4048>
2020-05-08 16:50:15,168 - e:\桌面\app\work_project\Car_Engine\code\CarEngine\codeV3\mid_run.py[line:58] - ERROR: malformed node or string: <_ast.Name object at 0x000001988A1B40B8>
2020-05-08 16:50:19,206 - e:\桌面\app\work_project\Car_Engine\code\CarEngine\codeV3\mid_run.py[line:58] - ERROR: malformed node or string: <_ast.Name object at 0x000001988A1B41D0>
2020-05-08 16:50:37,931 - e:\桌面\app\work_project\Car_Engine\code\CarEngine\codeV3\mid_run.py[line:58] - ERROR: malformed node or string: <_ast.Name object at 0x000001C2941EF048>
2020-05-08 16:50:44,947 - e:\桌面\app\work_project\Car_Engine\code\CarEngine\codeV3\mid_run.py[line:58] - ERROR: malformed node or string: <_ast.Name object at 0x000001C294209470>
2020-05-08 16:50:51,871 - e:\桌面\app\work_project\Car_Engine\code\CarEngine\codeV3\mid_run.py[line:58] - ERROR: malformed node or string: <_ast.Name object at 0x000001C294216588>
2020-05-08 17:03:47,313 - e:\桌面\app\work_project\Car_Engine\code\CarEngine\codeV3\mid_database_operate.py[line:57] - ERROR: list index out of range model:2 info get error
2020-05-08 17:03:47,781 - e:\桌面\app\work_project\Car_Engine\code\CarEngine\codeV3\mid_run.py[line:46] - ERROR: Abnormal end of training id 0000-05-07 15:43:54.152928
2020-05-08 17:03:51,789 - e:\桌面\app\work_project\Car_Engine\code\CarEngine\codeV3\mid_run.py[line:58] - ERROR: malformed node or string: <_ast.Name object at 0x000001835F1EF3C8>
2020-05-08 17:05:45,228 - e:\桌面\app\work_project\Car_Engine\code\CarEngine\codeV3\mid_run.py[line:58] - ERROR: malformed node or string: <_ast.Name object at 0x000001F0E2727EB8>
2020-05-08 17:05:49,246 - e:\桌面\app\work_project\Car_Engine\code\CarEngine\codeV3\mid_run.py[line:58] - ERROR: malformed node or string: <_ast.Name object at 0x000001F0E2727470>
2020-05-08 17:07:31,055 - e:\桌面\app\work_project\Car_Engine\code\CarEngine\codeV3\mid_run.py[line:59] - ERROR: malformed node or string: <_ast.Name object at 0x0000022F3F3B8EF0>
2020-05-08 17:25:57,441 - e:\桌面\app\work_project\Car_Engine\code\CarEngine\codeV3\mid_database_operate.py[line:57] - ERROR: list index out of range model:2 info get error
2020-05-08 17:25:57,928 - e:\桌面\app\work_project\Car_Engine\code\CarEngine\codeV3\mid_run.py[line:47] - ERROR: Abnormal end of training id 0000-05-07 15:43:54.152928
2020-05-08 17:33:27,537 - e:\桌面\app\work_project\Car_Engine\code\CarEngine\codeV3\mid_database_operate.py[line:57] - ERROR: list index out of range model:2 info get error
2020-05-08 17:33:27,914 - e:\桌面\app\work_project\Car_Engine\code\CarEngine\codeV3\mid_run.py[line:47] - ERROR: Abnormal end of training id 0000-05-07 15:43:54.152928
2020-05-08 17:33:32,102 - e:\桌面\app\work_project\Car_Engine\code\CarEngine\codeV3\mid_database_operate.py[line:57] - ERROR: list index out of range model:2 info get error
2020-05-08 17:33:32,425 - e:\桌面\app\work_project\Car_Engine\code\CarEngine\codeV3\mid_run.py[line:47] - ERROR: Abnormal end of training id 0000-05-07 15:43:54.152928
2020-05-08 17:35:12,354 - e:\桌面\app\work_project\Car_Engine\code\CarEngine\codeV3\mid_database_operate.py[line:57] - ERROR: list index out of range model:2 info get error
2020-05-08 17:35:12,669 - e:\桌面\app\work_project\Car_Engine\code\CarEngine\codeV3\mid_run.py[line:47] - ERROR: Abnormal end of training id 0000-05-07 15:43:54.152928
2020-05-08 19:41:28,336 - e:\桌面\app\work_project\Car_Engine\code\CarEngine\codeV3\mid_database_operate.py[line:57] - ERROR: list index out of range model:2 info get error
2020-05-08 19:41:29,004 - e:\桌面\app\work_project\Car_Engine\code\CarEngine\codeV3\mid_run.py[line:47] - ERROR: Abnormal end of training id 0000-05-07 15:43:54.152928
2020-05-08 19:51:45,455 - e:\桌面\app\work_project\Car_Engine\code\CarEngine\codeV3\mid_database_operate.py[line:57] - ERROR: list index out of range model:2 info get error
2020-05-08 20:18:18,435 - e:\桌面\app\work_project\Car_Engine\code\CarEngine\codeV3\mid_database_operate.py[line:61] - ERROR: list index out of range model:2 info get error
2020-05-08 20:32:18,916 - e:\桌面\app\work_project\Car_Engine\code\CarEngine\codeV3\mid_database_operate.py[line:96] - ERROR: model info get error 'NoneType' object has no attribute 'id'
2020-05-08 20:32:19,254 - e:\桌面\app\work_project\Car_Engine\code\CarEngine\codeV3\mid_run.py[line:111] - ERROR: init opt result save error 0000-05-07 15:43:54.152928
2020-05-08 20:38:44,407 - e:\桌面\app\work_project\Car_Engine\code\CarEngine\codeV3\mid_database_operate.py[line:130] - ERROR: data insert error (pymysql.err.IntegrityError) (1062, "Duplicate entry '2-V1' for key 'modelmanagement_datasett_training_model_id_model__95f493e0_uniq'") [SQL: 'INSERT INTO modelmanagement_datasettrainingmodel (training_time, accuracy_rate, model_version, model_fileaddr, dataset_list, training_model_id) VALUES (%(training_time)s, %(accuracy_rate)s, %(model_version)s, %(model_fileaddr)s, %(dataset_list)s, %(training_model_id)s)'] [parameters: {'training_time': '2020-05-08 20:38:36', 'accuracy_rate': 90.0, 'model_version': 'V1', 'model_fileaddr': 'http:/*?/', 'dataset_list': '1,2,3', 'training_model_id': 2}]
2020-05-08 20:38:44,475 - e:\桌面\app\work_project\Car_Engine\code\CarEngine\codeV3\mid_run.py[line:111] - ERROR: init opt result save error 0000-05-07 15:43:54.152928
2020-05-08 20:38:44,476 - e:\桌面\app\work_project\Car_Engine\code\CarEngine\codeV3\mid_run.py[line:61] - ERROR: 'train_model_id'
2020-05-08 20:38:49,967 - e:\桌面\app\work_project\Car_Engine\code\CarEngine\codeV3\mid_database_operate.py[line:130] - ERROR: data insert error (pymysql.err.IntegrityError) (1062, "Duplicate entry '2-V1' for key 'modelmanagement_datasett_training_model_id_model__95f493e0_uniq'") [SQL: 'INSERT INTO modelmanagement_datasettrainingmodel (training_time, accuracy_rate, model_version, model_fileaddr, dataset_list, training_model_id) VALUES (%(training_time)s, %(accuracy_rate)s, %(model_version)s, %(model_fileaddr)s, %(dataset_list)s, %(training_model_id)s)'] [parameters: {'training_time': '2020-05-08 20:38:36', 'accuracy_rate': 90.0, 'model_version': 'V1', 'model_fileaddr': 'http:/*?/', 'dataset_list': '1,2,3', 'training_model_id': 2}]
2020-05-08 20:38:50,037 - e:\桌面\app\work_project\Car_Engine\code\CarEngine\codeV3\mid_run.py[line:111] - ERROR: init opt result save error 0000-05-07 15:43:54.152928
2020-05-08 20:38:50,037 - e:\桌面\app\work_project\Car_Engine\code\CarEngine\codeV3\mid_run.py[line:61] - ERROR: 'train_model_id'
2020-05-08 20:46:17,403 - e:\桌面\app\work_project\Car_Engine\code\CarEngine\codeV3\mid_database_operate.py[line:130] - ERROR: data insert error (pymysql.err.IntegrityError) (1062, "Duplicate entry '2-V1' for key 'modelmanagement_datasett_training_model_id_model__95f493e0_uniq'") [SQL: 'INSERT INTO modelmanagement_datasettrainingmodel (training_time, accuracy_rate, model_version, model_fileaddr, dataset_list, training_model_id) VALUES (%(training_time)s, %(accuracy_rate)s, %(model_version)s, %(model_fileaddr)s, %(dataset_list)s, %(training_model_id)s)'] [parameters: {'training_time': '2020-05-08 20:45:46', 'accuracy_rate': 90.0, 'model_version': 'V1', 'model_fileaddr': 'http:/*?/', 'dataset_list': '1,2,3', 'training_model_id': 2}]
2020-05-08 20:46:17,504 - e:\桌面\app\work_project\Car_Engine\code\CarEngine\codeV3\mid_run.py[line:111] - ERROR: init opt result save error 0000-05-07 15:43:54.152928
2020-05-08 20:46:17,505 - e:\桌面\app\work_project\Car_Engine\code\CarEngine\codeV3\mid_run.py[line:61] - ERROR: 'train_model_id'
2020-05-08 20:46:27,377 - e:\桌面\app\work_project\Car_Engine\code\CarEngine\codeV3\mid_database_operate.py[line:130] - ERROR: data insert error (pymysql.err.IntegrityError) (1062, "Duplicate entry '2-V1' for key 'modelmanagement_datasett_training_model_id_model__95f493e0_uniq'") [SQL: 'INSERT INTO modelmanagement_datasettrainingmodel (training_time, accuracy_rate, model_version, model_fileaddr, dataset_list, training_model_id) VALUES (%(training_time)s, %(accuracy_rate)s, %(model_version)s, %(model_fileaddr)s, %(dataset_list)s, %(training_model_id)s)'] [parameters: {'training_time': '2020-05-08 20:45:46', 'accuracy_rate': 90.0, 'model_version': 'V1', 'model_fileaddr': 'http:/*?/', 'dataset_list': '1,2,3', 'training_model_id': 2}]
2020-05-08 20:46:27,492 - e:\桌面\app\work_project\Car_Engine\code\CarEngine\codeV3\mid_run.py[line:111] - ERROR: init opt result save error 0000-05-07 15:43:54.152928
2020-05-08 20:46:27,493 - e:\桌面\app\work_project\Car_Engine\code\CarEngine\codeV3\mid_run.py[line:61] - ERROR: 'train_model_id'
2020-05-08 20:47:48,595 - e:\桌面\app\work_project\Car_Engine\code\CarEngine\codeV3\mid_database_operate.py[line:130] - ERROR: data insert error (pymysql.err.IntegrityError) (1062, "Duplicate entry '2-V1' for key 'modelmanagement_datasett_training_model_id_model__95f493e0_uniq'") [SQL: 'INSERT INTO modelmanagement_datasettrainingmodel (training_time, accuracy_rate, model_version, model_fileaddr, dataset_list, training_model_id) VALUES (%(training_time)s, %(accuracy_rate)s, %(model_version)s, %(model_fileaddr)s, %(dataset_list)s, %(training_model_id)s)'] [parameters: {'training_time': '2020-05-08 20:47:44', 'accuracy_rate': 90.0, 'model_version': 'V1', 'model_fileaddr': 'http:/*?/', 'dataset_list': '1,2,3', 'training_model_id': 2}]
2020-05-08 20:47:48,663 - e:\桌面\app\work_project\Car_Engine\code\CarEngine\codeV3\mid_run.py[line:111] - ERROR: init opt result save error 0000-05-07 15:43:54.152928
2020-05-08 20:47:48,664 - e:\桌面\app\work_project\Car_Engine\code\CarEngine\codeV3\mid_run.py[line:61] - ERROR: 'train_model_id'
2020-05-08 21:18:28,591 - e:\桌面\app\work_project\Car_Engine\code\CarEngine\codeV3\mid_run.py[line:61] - ERROR: must be str, not tuple
2020-05-08 21:18:35,537 - e:\桌面\app\work_project\Car_Engine\code\CarEngine\codeV3\mid_run.py[line:61] - ERROR: must be str, not tuple
2020-05-08 21:18:40,601 - e:\桌面\app\work_project\Car_Engine\code\CarEngine\codeV3\mid_run.py[line:61] - ERROR: must be str, not tuple
2020-05-09 09:31:58,825 - e:\桌面\app\work_project\Car_Engine\code\CarEngine\codeV3\mid_database_operate.py[line:130] - ERROR: data insert error (pymysql.err.IntegrityError) (1062, "Duplicate entry '2-V10' for key 'modelmanagement_datasett_training_model_id_model__95f493e0_uniq'") [SQL: 'INSERT INTO modelmanagement_datasettrainingmodel (training_time, accuracy_rate, model_version, model_fileaddr, dataset_list, training_model_id) VALUES (%(training_time)s, %(accuracy_rate)s, %(model_version)s, %(model_fileaddr)s, %(dataset_list)s, %(training_model_id)s)'] [parameters: {'training_time': '2020-05-09 09:31:57', 'accuracy_rate': 90.0, 'model_version': 'V10', 'model_fileaddr': 'http:/*?/', 'dataset_list': '3, 4, 5', 'training_model_id': 2}]
2020-05-09 09:31:58,828 - e:\桌面\app\work_project\Car_Engine\code\CarEngine\codeV3\mid_run.py[line:112] - ERROR: init opt result save error 0000-05-07 15:43:54.152928
2020-05-09 09:31:58,848 - e:\桌面\app\work_project\Car_Engine\code\CarEngine\codeV3\mid_run.py[line:61] - ERROR: 'train_model_id'
2020-05-09 09:32:03,807 - e:\桌面\app\work_project\Car_Engine\code\CarEngine\codeV3\mid_database_operate.py[line:130] - ERROR: data insert error (pymysql.err.IntegrityError) (1062, "Duplicate entry '2-V10' for key 'modelmanagement_datasett_training_model_id_model__95f493e0_uniq'") [SQL: 'INSERT INTO modelmanagement_datasettrainingmodel (training_time, accuracy_rate, model_version, model_fileaddr, dataset_list, training_model_id) VALUES (%(training_time)s, %(accuracy_rate)s, %(model_version)s, %(model_fileaddr)s, %(dataset_list)s, %(training_model_id)s)'] [parameters: {'training_time': '2020-05-09 09:31:57', 'accuracy_rate': 90.0, 'model_version': 'V10', 'model_fileaddr': 'http:/*?/', 'dataset_list': '3, 4, 5', 'training_model_id': 2}]
2020-05-09 09:32:03,813 - e:\桌面\app\work_project\Car_Engine\code\CarEngine\codeV3\mid_run.py[line:112] - ERROR: init opt result save error 0000-05-07 15:43:54.152928
2020-05-09 09:32:03,813 - e:\桌面\app\work_project\Car_Engine\code\CarEngine\codeV3\mid_run.py[line:61] - ERROR: 'train_model_id'
2020-05-09 09:32:09,049 - e:\桌面\app\work_project\Car_Engine\code\CarEngine\codeV3\mid_database_operate.py[line:130] - ERROR: data insert error (pymysql.err.IntegrityError) (1062, "Duplicate entry '2-V10' for key 'modelmanagement_datasett_training_model_id_model__95f493e0_uniq'") [SQL: 'INSERT INTO modelmanagement_datasettrainingmodel (training_time, accuracy_rate, model_version, model_fileaddr, dataset_list, training_model_id) VALUES (%(training_time)s, %(accuracy_rate)s, %(model_version)s, %(model_fileaddr)s, %(dataset_list)s, %(training_model_id)s)'] [parameters: {'training_time': '2020-05-09 09:31:57', 'accuracy_rate': 90.0, 'model_version': 'V10', 'model_fileaddr': 'http:/*?/', 'dataset_list': '3, 4, 5', 'training_model_id': 2}]
2020-05-09 09:32:09,069 - e:\桌面\app\work_project\Car_Engine\code\CarEngine\codeV3\mid_run.py[line:112] - ERROR: init opt result save error 0000-05-07 15:43:54.152928
2020-05-09 09:32:09,070 - e:\桌面\app\work_project\Car_Engine\code\CarEngine\codeV3\mid_run.py[line:61] - ERROR: 'train_model_id'
2020-05-09 10:05:52,552 - e:\桌面\app\work_project\Car_Engine\code\CarEngine\codeV3\mid_run.py[line:61] - ERROR: 'dict' object is not callable
2020-05-09 10:11:29,996 - e:\桌面\app\work_project\Car_Engine\code\CarEngine\codeV3\mid_run.py[line:61] - ERROR: 'dict' object is not callable
2020-05-09 10:12:05,772 - e:\桌面\app\work_project\Car_Engine\code\CarEngine\codeV3\mid_run.py[line:61] - ERROR: 'dict' object is not callable
2020-05-09 10:13:03,514 - e:\桌面\app\work_project\Car_Engine\code\CarEngine\codeV3\mid_run.py[line:61] - ERROR: 'dict' object is not callable
2020-05-09 10:17:14,515 - e:\桌面\app\work_project\Car_Engine\code\CarEngine\codeV3\mid_run.py[line:61] - ERROR: 'dict' object is not callable
2020-05-09 10:20:14,564 - e:\桌面\app\work_project\Car_Engine\code\CarEngine\codeV3\mid_run.py[line:61] - ERROR: 'dict' object is not callable
2020-05-09 10:22:57,329 - e:\桌面\app\work_project\Car_Engine\code\CarEngine\codeV3\mid_database_operate.py[line:130] - ERROR: data insert error (pymysql.err.IntegrityError) (1062, "Duplicate entry '1-V10' for key 'modelmanagement_datasett_training_model_id_model__95f493e0_uniq'") [SQL: 'INSERT INTO modelmanagement_datasettrainingmodel (training_time, accuracy_rate, model_version, model_fileaddr, dataset_list, training_model_id) VALUES (%(training_time)s, %(accuracy_rate)s, %(model_version)s, %(model_fileaddr)s, %(dataset_list)s, %(training_model_id)s)'] [parameters: {'training_time': '2020-05-09 10:21:46', 'accuracy_rate': 90.0, 'model_version': 'V10', 'model_fileaddr': "/('D:/svn', 'ModelFiles')/test_model_V10.h5", 'dataset_list': "'2', '3', '4'", 'training_model_id': 1}]
2020-05-09 10:22:57,375 - e:\桌面\app\work_project\Car_Engine\code\CarEngine\codeV3\mid_run.py[line:117] - ERROR: init opt result save error 1588988207.9541364
2020-05-09 10:26:12,117 - e:\桌面\app\work_project\Car_Engine\code\CarEngine\codeV3\mid_database_operate.py[line:70] - ERROR: list index out of range model:5 info get error
2020-05-09 10:26:12,118 - e:\桌面\app\work_project\Car_Engine\code\CarEngine\codeV3\mid_run.py[line:61] - ERROR: 'bool' object is not subscriptable
2020-05-09 10:29:38,644 - e:\桌面\app\work_project\Car_Engine\code\CarEngine\codeV3\mid_run.py[line:61] - ERROR: 'dict' object is not callable
2020-05-09 10:38:16,872 - e:\桌面\app\work_project\Car_Engine\code\CarEngine\codeV3\mid_database_operate.py[line:70] - ERROR: list index out of range model:2 info get error
2020-05-09 10:38:16,872 - e:\桌面\app\work_project\Car_Engine\code\CarEngine\codeV3\mid_run.py[line:61] - ERROR: 'bool' object is not subscriptable
2020-05-09 10:40:45,351 - e:\桌面\app\work_project\Car_Engine\code\CarEngine\codeV3\mid_database_operate.py[line:130] - ERROR: data insert error (pymysql.err.IntegrityError) (1062, "Duplicate entry '2-V10' for key 'modelmanagement_datasett_training_model_id_model__95f493e0_uniq'") [SQL: 'INSERT INTO modelmanagement_datasettrainingmodel (training_time, accuracy_rate, model_version, model_fileaddr, dataset_list, training_model_id) VALUES (%(training_time)s, %(accuracy_rate)s, %(model_version)s, %(model_fileaddr)s, %(dataset_list)s, %(training_model_id)s)'] [parameters: {'training_time': '2020-05-09 10:40:43', 'accuracy_rate': 90.0, 'model_version': 'V10', 'model_fileaddr': "/('', ':')/进气阀测试模型_V10.h5", 'dataset_list': '2, 3, 4', 'training_model_id': 2}]
2020-05-09 10:40:45,380 - e:\桌面\app\work_project\Car_Engine\code\CarEngine\codeV3\mid_run.py[line:116] - ERROR: init opt result save error 1588991987.0258958
2020-05-09 10:40:45,380 - e:\桌面\app\work_project\Car_Engine\code\CarEngine\codeV3\mid_run.py[line:61] - ERROR: 'train_model_id'
2020-05-09 10:46:11,998 - e:\桌面\app\work_project\Car_Engine\code\CarEngine\codeV3\mid_database_operate.py[line:130] - ERROR: data insert error (pymysql.err.IntegrityError) (1062, "Duplicate entry '2-V10' for key 'modelmanagement_datasett_training_model_id_model__95f493e0_uniq'") [SQL: 'INSERT INTO modelmanagement_datasettrainingmodel (training_time, accuracy_rate, model_version, model_fileaddr, dataset_list, training_model_id) VALUES (%(training_time)s, %(accuracy_rate)s, %(model_version)s, %(model_fileaddr)s, %(dataset_list)s, %(training_model_id)s)'] [parameters: {'training_time': '2020-05-09 10:41:44', 'accuracy_rate': 90.0, 'model_version': 'V10', 'model_fileaddr': "/('', ':')/进气阀测试模型_V10_V10.h5", 'dataset_list': '2, 3, 4', 'training_model_id': 2}]
2020-05-09 10:46:12,016 - e:\桌面\app\work_project\Car_Engine\code\CarEngine\codeV3\mid_run.py[line:116] - ERROR: init opt result save error 1588991987.0258958
2020-05-09 10:47:33,040 - e:\桌面\app\work_project\Car_Engine\code\CarEngine\codeV3\mid_database_operate.py[line:130] - ERROR: data insert error (pymysql.err.IntegrityError) (1062, "Duplicate entry '2-V10' for key 'modelmanagement_datasett_training_model_id_model__95f493e0_uniq'") [SQL: 'INSERT INTO modelmanagement_datasettrainingmodel (training_time, accuracy_rate, model_version, model_fileaddr, dataset_list, training_model_id) VALUES (%(training_time)s, %(accuracy_rate)s, %(model_version)s, %(model_fileaddr)s, %(dataset_list)s, %(training_model_id)s)'] [parameters: {'training_time': '2020-05-09 10:47:27', 'accuracy_rate': 90.0, 'model_version': 'V10', 'model_fileaddr': "/('', ':')/进气阀测试模型_V10_V10_V10_V10.h5", 'dataset_list': '2, 3, 4', 'training_model_id': 2}]
2020-05-09 10:47:33,059 - e:\桌面\app\work_project\Car_Engine\code\CarEngine\codeV3\mid_run.py[line:116] - ERROR: init opt result save error 1588991987.0258958
2020-05-09 10:47:33,064 - e:\桌面\app\work_project\Car_Engine\code\CarEngine\codeV3\mid_run.py[line:61] - ERROR: 'train_model_id'
2020-05-09 10:47:58,010 - e:\桌面\app\work_project\Car_Engine\code\CarEngine\codeV3\mid_database_operate.py[line:130] - ERROR: data insert error (pymysql.err.IntegrityError) (1062, "Duplicate entry '2-V10' for key 'modelmanagement_datasett_training_model_id_model__95f493e0_uniq'") [SQL: 'INSERT INTO modelmanagement_datasettrainingmodel (training_time, accuracy_rate, model_version, model_fileaddr, dataset_list, training_model_id) VALUES (%(training_time)s, %(accuracy_rate)s, %(model_version)s, %(model_fileaddr)s, %(dataset_list)s, %(training_model_id)s)'] [parameters: {'training_time': '2020-05-09 10:47:27', 'accuracy_rate': 90.0, 'model_version': 'V10', 'model_fileaddr': "/('', ':')/进气阀测试模型_V10_V10_V10_V10_V10.h5", 'dataset_list': '2, 3, 4', 'training_model_id': 2}]
2020-05-09 10:47:58,023 - e:\桌面\app\work_project\Car_Engine\code\CarEngine\codeV3\mid_run.py[line:116] - ERROR: init opt result save error 1588991987.0258958
2020-05-09 10:47:58,027 - e:\桌面\app\work_project\Car_Engine\code\CarEngine\codeV3\mid_run.py[line:61] - ERROR: 'train_model_id'
2020-05-09 10:50:59,819 - e:\桌面\app\work_project\Car_Engine\code\CarEngine\codeV3\mid_database_operate.py[line:130] - ERROR: data insert error (pymysql.err.IntegrityError) (1062, "Duplicate entry '2-V10' for key 'modelmanagement_datasett_training_model_id_model__95f493e0_uniq'") [SQL: 'INSERT INTO modelmanagement_datasettrainingmodel (training_time, accuracy_rate, model_version, model_fileaddr, dataset_list, training_model_id) VALUES (%(training_time)s, %(accuracy_rate)s, %(model_version)s, %(model_fileaddr)s, %(dataset_list)s, %(training_model_id)s)'] [parameters: {'training_time': '2020-05-09 10:47:27', 'accuracy_rate': 90.0, 'model_version': 'V10', 'model_fileaddr': "/('', ':')/进气阀测试模型_V10_V10_V10_V10_V10_V10.h5", 'dataset_list': '2, 3, 4', 'training_model_id': 2}]
2020-05-09 10:58:00,649 - e:\桌面\app\work_project\Car_Engine\code\CarEngine\codeV3\mid_database_operate.py[line:130] - ERROR: data insert error (pymysql.err.IntegrityError) (1062, "Duplicate entry '2-V10' for key 'modelmanagement_datasett_training_model_id_model__95f493e0_uniq'") [SQL: 'INSERT INTO modelmanagement_datasettrainingmodel (training_time, accuracy_rate, model_version, model_fileaddr, dataset_list, training_model_id) VALUES (%(training_time)s, %(accuracy_rate)s, %(model_version)s, %(model_fileaddr)s, %(dataset_list)s, %(training_model_id)s)'] [parameters: {'training_time': '2020-05-09 10:57:58', 'accuracy_rate': 90.0, 'model_version': 'V10', 'model_fileaddr': '/ModelFiles/进气阀测试模型_V10_V10_V10_V10_V10_V10_V10.h5', 'dataset_list': '2, 3, 4', 'training_model_id': 2}]
2020-05-09 10:58:00,664 - e:\桌面\app\work_project\Car_Engine\code\CarEngine\codeV3\mid_run.py[line:116] - ERROR: init opt result save error 1588991987.0258958
2020-05-09 10:58:00,664 - e:\桌面\app\work_project\Car_Engine\code\CarEngine\codeV3\mid_run.py[line:61] - ERROR: 'train_model_id'
2020-05-09 10:58:07,823 - e:\桌面\app\work_project\Car_Engine\code\CarEngine\codeV3\mid_database_operate.py[line:130] - ERROR: data insert error (pymysql.err.IntegrityError) (1062, "Duplicate entry '2-V10' for key 'modelmanagement_datasett_training_model_id_model__95f493e0_uniq'") [SQL: 'INSERT INTO modelmanagement_datasettrainingmodel (training_time, accuracy_rate, model_version, model_fileaddr, dataset_list, training_model_id) VALUES (%(training_time)s, %(accuracy_rate)s, %(model_version)s, %(model_fileaddr)s, %(dataset_list)s, %(training_model_id)s)'] [parameters: {'training_time': '2020-05-09 10:57:58', 'accuracy_rate': 90.0, 'model_version': 'V10', 'model_fileaddr': '/ModelFiles/进气阀测试模型_V10_V10_V10_V10_V10_V10_V10_V10.h5', 'dataset_list': '2, 3, 4', 'training_model_id': 2}]
2020-05-09 10:58:07,828 - e:\桌面\app\work_project\Car_Engine\code\CarEngine\codeV3\mid_run.py[line:116] - ERROR: init opt result save error 1588991987.0258958
2020-05-09 10:58:07,844 - e:\桌面\app\work_project\Car_Engine\code\CarEngine\codeV3\mid_run.py[line:61] - ERROR: 'train_model_id'
2020-05-09 10:58:15,215 - e:\桌面\app\work_project\Car_Engine\code\CarEngine\codeV3\mid_database_operate.py[line:130] - ERROR: data insert error (pymysql.err.IntegrityError) (1062, "Duplicate entry '2-V10' for key 'modelmanagement_datasett_training_model_id_model__95f493e0_uniq'") [SQL: 'INSERT INTO modelmanagement_datasettrainingmodel (training_time, accuracy_rate, model_version, model_fileaddr, dataset_list, training_model_id) VALUES (%(training_time)s, %(accuracy_rate)s, %(model_version)s, %(model_fileaddr)s, %(dataset_list)s, %(training_model_id)s)'] [parameters: {'training_time': '2020-05-09 10:57:58', 'accuracy_rate': 90.0, 'model_version': 'V10', 'model_fileaddr': '/ModelFiles/进气阀测试模型_V10_V10_V10_V10_V10_V10_V10_V10_V10.h5', 'dataset_list': '2, 3, 4', 'training_model_id': 2}]
2020-05-09 10:58:15,230 - e:\桌面\app\work_project\Car_Engine\code\CarEngine\codeV3\mid_run.py[line:116] - ERROR: init opt result save error 1588991987.0258958
2020-05-09 10:58:15,231 - e:\桌面\app\work_project\Car_Engine\code\CarEngine\codeV3\mid_run.py[line:61] - ERROR: 'train_model_id'
2020-05-09 11:03:44,201 - e:\桌面\app\work_project\Car_Engine\code\CarEngine\codeV3\mid_database_operate.py[line:130] - ERROR: data insert error (pymysql.err.IntegrityError) (1062, "Duplicate entry '2-V10' for key 'modelmanagement_datasett_training_model_id_model__95f493e0_uniq'") [SQL: 'INSERT INTO modelmanagement_datasettrainingmodel (training_time, accuracy_rate, model_version, model_fileaddr, dataset_list, training_model_id) VALUES (%(training_time)s, %(accuracy_rate)s, %(model_version)s, %(model_fileaddr)s, %(dataset_list)s, %(training_model_id)s)'] [parameters: {'training_time': '2020-05-09 11:03:42', 'accuracy_rate': 90.0, 'model_version': 'V10', 'model_fileaddr': '/ModelFiles/进气阀测试模型_V10.h5', 'dataset_list': '2, 3, 4', 'training_model_id': 2}]
2020-05-09 11:03:44,217 - e:\桌面\app\work_project\Car_Engine\code\CarEngine\codeV3\mid_run.py[line:116] - ERROR: init opt result save error 1588993363.716316
2020-05-09 11:03:44,218 - e:\桌面\app\work_project\Car_Engine\code\CarEngine\codeV3\mid_run.py[line:61] - ERROR: 'train_model_id'
2020-05-09 11:07:09,726 - e:\桌面\app\work_project\Car_Engine\code\CarEngine\codeV3\mid_database_operate.py[line:130] - ERROR: data insert error (pymysql.err.IntegrityError) (1062, "Duplicate entry '2-V10' for key 'modelmanagement_datasett_training_model_id_model__95f493e0_uniq'") [SQL: 'INSERT INTO modelmanagement_datasettrainingmodel (training_time, accuracy_rate, model_version, model_fileaddr, dataset_list, training_model_id) VALUES (%(training_time)s, %(accuracy_rate)s, %(model_version)s, %(model_fileaddr)s, %(dataset_list)s, %(training_model_id)s)'] [parameters: {'training_time': '2020-05-09 11:06:21', 'accuracy_rate': 90.0, 'model_version': 'V10', 'model_fileaddr': '/ModelFiles/进气阀测试模型_V10_V10.h5', 'dataset_list': '2, 3, 4', 'training_model_id': 2}]
2020-05-09 11:07:09,743 - e:\桌面\app\work_project\Car_Engine\code\CarEngine\codeV3\mid_run.py[line:116] - ERROR: init opt result save error 1588993363.716316
2020-05-09 11:07:09,751 - e:\桌面\app\work_project\Car_Engine\code\CarEngine\codeV3\mid_run.py[line:61] - ERROR: 'train_model_id'
2020-05-09 11:11:38,296 - e:\桌面\app\work_project\Car_Engine\code\CarEngine\codeV3\mid_database_operate.py[line:130] - ERROR: data insert error (pymysql.err.IntegrityError) (1062, "Duplicate entry '2-V10' for key 'modelmanagement_datasett_training_model_id_model__95f493e0_uniq'") [SQL: 'INSERT INTO modelmanagement_datasettrainingmodel (training_time, accuracy_rate, model_version, model_fileaddr, dataset_list, training_model_id) VALUES (%(training_time)s, %(accuracy_rate)s, %(model_version)s, %(model_fileaddr)s, %(dataset_list)s, %(training_model_id)s)'] [parameters: {'training_time': '2020-05-09 11:07:56', 'accuracy_rate': 90.0, 'model_version': 'V10', 'model_fileaddr': '/ModelFiles/进气阀测试模型_V10_V10_V10.h5', 'dataset_list': '2, 3, 4', 'training_model_id': 2}]
2020-05-09 11:20:30,915 - e:\桌面\app\work_project\Car_Engine\code\CarEngine\codeV3\mid_database_operate.py[line:130] - ERROR: data insert error (pymysql.err.IntegrityError) (1062, "Duplicate entry '2-V11' for key 'modelmanagement_datasett_training_model_id_model__95f493e0_uniq'") [SQL: 'INSERT INTO modelmanagement_datasettrainingmodel (training_time, accuracy_rate, model_version, model_fileaddr, dataset_list, training_model_id) VALUES (%(training_time)s, %(accuracy_rate)s, %(model_version)s, %(model_fileaddr)s, %(dataset_list)s, %(training_model_id)s)'] [parameters: {'training_time': '2020-05-09 11:20:24', 'accuracy_rate': 90.0, 'model_version': 'V11', 'model_fileaddr': '/ModelFiles/进气阀测试模型_V10_V10_V10_V10_V11_V11.h5', 'dataset_list': '2, 3, 4', 'training_model_id': 2}]
2020-05-09 11:20:30,921 - e:\桌面\app\work_project\Car_Engine\code\CarEngine\codeV3\mid_run.py[line:116] - ERROR: init opt result save error 1588993363.716316
2020-05-09 11:20:30,921 - e:\桌面\app\work_project\Car_Engine\code\CarEngine\codeV3\mid_run.py[line:61] - ERROR: 'train_model_id'
2020-05-09 11:22:41,966 - e:\桌面\app\work_project\Car_Engine\code\CarEngine\codeV3\mid_database_operate.py[line:61] - ERROR: list index out of range model:2 info get error
2020-05-09 11:22:41,967 - e:\桌面\app\work_project\Car_Engine\code\CarEngine\codeV3\mid_run.py[line:61] - ERROR: 'bool' object is not subscriptable
2020-05-09 11:22:46,537 - e:\桌面\app\work_project\Car_Engine\code\CarEngine\codeV3\mid_database_operate.py[line:61] - ERROR: list index out of range model:2 info get error
2020-05-09 11:22:46,538 - e:\桌面\app\work_project\Car_Engine\code\CarEngine\codeV3\mid_run.py[line:61] - ERROR: 'bool' object is not subscriptable
2020-05-09 11:23:01,370 - e:\桌面\app\work_project\Car_Engine\code\CarEngine\codeV3\mid_database_operate.py[line:130] - ERROR: data insert error (pymysql.err.IntegrityError) (1062, "Duplicate entry '2-V11' for key 'modelmanagement_datasett_training_model_id_model__95f493e0_uniq'") [SQL: 'INSERT INTO modelmanagement_datasettrainingmodel (training_time, accuracy_rate, model_version, model_fileaddr, dataset_list, training_model_id) VALUES (%(training_time)s, %(accuracy_rate)s, %(model_version)s, %(model_fileaddr)s, %(dataset_list)s, %(training_model_id)s)'] [parameters: {'training_time': '2020-05-09 11:23:00', 'accuracy_rate': 90.0, 'model_version': 'V11', 'model_fileaddr': '/ModelFiles/进气阀测试模型_V10_V10_V10_V10_V11_V11_V11.h5', 'dataset_list': '2, 3, 4', 'training_model_id': 2}]
2020-05-09 11:23:01,374 - e:\桌面\app\work_project\Car_Engine\code\CarEngine\codeV3\mid_run.py[line:116] - ERROR: init opt result save error 1588993363.716316
2020-05-09 11:23:01,386 - e:\桌面\app\work_project\Car_Engine\code\CarEngine\codeV3\mid_run.py[line:61] - ERROR: 'train_model_id'
2020-05-09 11:23:06,558 - e:\桌面\app\work_project\Car_Engine\code\CarEngine\codeV3\mid_database_operate.py[line:130] - ERROR: data insert error (pymysql.err.IntegrityError) (1062, "Duplicate entry '2-V11' for key 'modelmanagement_datasett_training_model_id_model__95f493e0_uniq'") [SQL: 'INSERT INTO modelmanagement_datasettrainingmodel (training_time, accuracy_rate, model_version, model_fileaddr, dataset_list, training_model_id) VALUES (%(training_time)s, %(accuracy_rate)s, %(model_version)s, %(model_fileaddr)s, %(dataset_list)s, %(training_model_id)s)'] [parameters: {'training_time': '2020-05-09 11:23:00', 'accuracy_rate': 90.0, 'model_version': 'V11', 'model_fileaddr': '/ModelFiles/进气阀测试模型_V10_V10_V10_V10_V11_V11_V11_V11.h5', 'dataset_list': '2, 3, 4', 'training_model_id': 2}]
2020-05-09 11:23:06,569 - e:\桌面\app\work_project\Car_Engine\code\CarEngine\codeV3\mid_run.py[line:116] - ERROR: init opt result save error 1588993363.716316
2020-05-09 11:23:06,583 - e:\桌面\app\work_project\Car_Engine\code\CarEngine\codeV3\mid_run.py[line:61] - ERROR: 'train_model_id'
2020-05-09 11:23:45,006 - e:\桌面\app\work_project\Car_Engine\code\CarEngine\codeV3\mid_database_operate.py[line:130] - ERROR: data insert error (pymysql.err.IntegrityError) (1062, "Duplicate entry '2-V12' for key 'modelmanagement_datasett_training_model_id_model__95f493e0_uniq'") [SQL: 'INSERT INTO modelmanagement_datasettrainingmodel (training_time, accuracy_rate, model_version, model_fileaddr, dataset_list, training_model_id) VALUES (%(training_time)s, %(accuracy_rate)s, %(model_version)s, %(model_fileaddr)s, %(dataset_list)s, %(training_model_id)s)'] [parameters: {'training_time': '2020-05-09 11:23:39', 'accuracy_rate': 90.0, 'model_version': 'V12', 'model_fileaddr': '/ModelFiles/进气阀测试模型_V10_V10_V10_V10_V11_V11_V11_V11_V11_V12_V12.h5', 'dataset_list': '2, 3, 4', 'training_model_id': 2}]
2020-05-09 11:23:45,010 - e:\桌面\app\work_project\Car_Engine\code\CarEngine\codeV3\mid_run.py[line:116] - ERROR: init opt result save error 1588993363.716316
2020-05-09 11:23:45,011 - e:\桌面\app\work_project\Car_Engine\code\CarEngine\codeV3\mid_run.py[line:61] - ERROR: 'train_model_id'
